Workbook
Name \0: #REF!
Name \A: #REF!
Name \B: [1]A!#REF!
Name \C: #REF!
Name \D: [1]A!#REF!
Name \E: [1]A!#REF!
Name \F: #REF!
Name \G: [1]A!#REF!
Name \H: #REF!
Name \H1: #REF!
Name \H2: #REF!
Name \H4: #REF!
Name \H5: #REF!
Name \H6: #REF!
Name \H7: #REF!
Name \J: #REF!
Name \K: #REF!
Name \L: [1]A!#REF!
Name \M: [1]A!#REF!
Name \N: #REF!
Name \O: #REF!
Name \P: #REF!
Name \R: [1]A!#REF!
Name \S: #REF!
Name \T: [1]A!#REF!
Name \U: [1]A!#REF!
Name \V: [1]A!#REF!
Name \W: #REF!
Name \X: [1]A!#REF!
Name \Y: #REF!
Name \Z: [1]A!#REF!
Name _: #REF!
Name __?___RIGHT__?_: #REF!
Name ___: [2]ANALIS!#REF!
Name ____________________________DIV11: #REF!
Name ___________________________MMM19: '[3]4-Basic Price'!$F$71
Name __________________________DIV11: #REF!
Name __________________________EEE02: #REF!
Name __________________________EEE05: #REF!
Name __________________________EEE06: #REF!
Name __________________________EEE07: #REF!
Name __________________________EEE08: #REF!
Name __________________________EEE09: #REF!
Name __________________________EEE10: #REF!
Name __________________________EEE11: #REF!
Name __________________________EEE13: #REF!
Name __________________________EEE15: #REF!
Name __________________________EEE16: #REF!
Name __________________________EEE17: #REF!
Name __________________________EEE22: #REF!
Name __________________________EEE23: #REF!
Name __________________________EEE27: #REF!
Name __________________________EEE29: #REF!
Name __________________________HAL2: #REF!
Name __________________________HAL5: #REF!
Name __________________________HAL6: #REF!
Name __________________________HAL7: #REF!
Name __________________________HAL8: #REF!
Name __________________________MMM19: '[4]4-Basic Price'!$F$69
Name __________________________MMM38: '[4]4-Basic Price'!#REF!

Sheet INFORMASI
A1: AHS CIPTA KARYA PEK PERSIAPAN, STRUKTUR, ARSITEKTURAL
A2: DIBUAT BERDASARKAN SURAT EDARAN BINA KONSTRUKSI NO. 182 TAHUN 2025
A5: ANALISA HARGA SATUAN INI
A6: TERDIRI DARI HSP (HARGA SATUAN PEKERJAAN), AHS (ANALISA HARGA SATUAN), HSD (HARGA SATUAN DASAR) UPAH BAHAN ALAT
A8: Untuk pembuatan RAB harap diperhatikan penjumlahan dalam analisa karena bisa berubah setiap program excel sehingga mengakibatkan ketidak validan perhitungan
B11: BACA DULU :
B12: 1. Program ini terdiri dari HSP (Harga Satuan Pekerjaan), AHS (Analisa harga satuan), HSD (Harga Satuan Dasar) Upah dan Bahan
B13: 2. Cukup merubah harga HSD maka AHS dan HSP akan langsung berubah menyesuaikan
B14: 3. AHS ini dibuat berdasarkan SE Bina Konstruksi No. 182 tahun 2025, sebagai Update dari SE BK No. 30 Tahun 2025
B15: 4. Untuk membuat RAB, cukup cari pekerjaan yang sesuai di HSP, lalu dari HSP cek AHS, dari AHS kemudian rubah harga bahan di HSD, otomatis AHS dan HSP akan berubah menyesuaikan, harga pada HSP bisa digunakan untuk RAB
B16: 5. Harga default untuk Bahan dan alat adalah Rp.10.000 yang bisa diubah sesuai harga setempat

Sheet BOQ
B1: RENCANA ANGGARAN BIAYA
B3: PEKERJAAN | D3: : RUMAH TINGGAL LANTAI 1
B4: LOKASI | D4: :
B5: TAHUN | D5: :
B7: NO | C7: KODE ANALISA | D7: URAIAN PEKERJAAN | E7: SATUAN | F7: VOLUME | G7: HARGA SATUAN (Rp.) | H7: JUMLAH (Rp.)
B9: A | D9: PEKERJAAN PERSIAPAN
B10: 1 | C10: 1.1.2.4.b | D10: Pembuatan 1m2 direksi keet (kantor), los kerja dan gudang | E10: m2 | F10: =[423]VOLGUDANG!$Q$43 -> 12 | G10: ='HSP PRSPN,STR,ARS'!D20 -> 1001734.9 | H10: =G10*F10 -> 12020819 | I10: =VLOOKUP(E10,'HSD PSPN,STR,ARS'!#REF!,4,FALSE) -> #REF! | J10: =VLOOKUP(F10,'HSD PSPN,STR,ARS'!#REF!,4,FALSE) -> #REF!
B11: 2 | C11: 1.1.3.1 | D11: 1 m2 pembersihan dan pengupasan permukaan tanah (stiping) sd tanaman Φ 2 cm | E11: m2 | F11: ='[423]PEMBERSIHAN LAHAN'!$Q$43 -> 120 | G11: ='HSP PRSPN,STR,ARS'!D27 -> 22000 | H11: =G11*F11 -> 2640000
B12: 3 | C12: 1.1.4.2 | D12: Pasangan 1 m ' bouwplank | E12: m' | F12: =[423]BOWPLANK!$Q$40 -> 41.65 | G12: ='HSP PRSPN,STR,ARS'!D47 -> 4070 | H12: =G12*F12 -> 169515.5
B13: 4 | D13: Air kerja | E13: ls | F13: 1 | G13: 500000 | H13: =G13*F13 -> 500000
B14: 5 | D14: Perizinan | E14: ls | F14: 1 | G14: 5000000 | H14: =G14*F14 -> 5000000
B15: JUMLAH A | H15: =SUM(H10:H14) -> 20330334
B16: B | D16: PEKERJAAN STRUKTUR
B17: I. | D17: Pekerjaan Pondasi
B18: I.1 | D18: Pondasi Batu Belah
B19: a | C19: 1.2.1.1.1 | D19: Penggalian 1 m³ tanah biasa sedalam 0 sd 1 m untuk volume sd 200 m3 secara manual | E19: m3 | F19: ='[424]VOL GALIAN POND BATU BELAH'!$Q$48 -> 16.2435 | G19: ='HSP PRSPN,STR,ARS'!D56 -> 90860 | H19: =G19*F19 -> 1475884.4
B20: b | C20: 1.3.1.2 | D20: 1 m3 Urukan dengan Pasir Uruk untuk volume s.d 200 m3 tanpa pemadatan secara manual | E20: m3 | F20: ='[424]VOL PASIR URUG '!$Q$49 -> 1.2495 | G20: ='HSP PRSPN,STR,ARS'!D130 -> 49500 | H20: =G20*F20 -> 61850.25
B21: c | C21: 2.2.2.1.1 | D21: Pemasangan 1 m³ batu kosong (Aanstamping) | E21: m3 | F21: ='[424]VOL AANSTAMPANG '!$Q$48 -> 2.499 | G21: ='HSP PRSPN,STR,ARS'!D350 -> 177397 | H21: =G21*F21 -> 443315.1
B22: d | C22: 2.2.2.1.9 | D22: Pemasangan 1 m³ pondasi Batu Belah Mortar Tipe O (2,4 Mpa) setara 1SP : 5PP, cara semi mekanis | E22: m3 | F22: ='[424]VOL PSGN BATU BELAH'!$Q$47 -> 12.182625 | G22: ='HSP PRSPN,STR,ARS'!D358 -> 1719171 | H22: =G22*F22 -> 20944016
B23: I.2 | D23: Pondasi Foot Plate
B24: a | C24: 1.2.1.1.1 | D24: Penggalian 1 m³ tanah biasa sedalam 0 sd 1 m untuk volume sd 200 m3 secara manual | E24: m3 | G24: =G19 -> 90860 | H24: =G24*F24 -> 0
B25: b | C25: 2.2.1.4.1 | D25: 1 m3 beton mutu rendah f'c 7,5 Mpa Slump (100 ± 25) mm, agregat maks 19 mm secara manual | E25: m3 | G25: =G20 -> 49500 | H25: =G25*F25 -> 0
B27: c | C27: 2.2.1.3.1 | D27: Pemasangan 1 m² bekisting untuk pondasi telapak (3 kali pakai) | E27: m2 | G27: ='HSP PRSPN,STR,ARS'!D278 -> 110946 | H27: =G27*F27 -> 0
B28: d | C28: 2.2.1.1.1 | D28: 1 Kg Penulangan slab untuk BjTP diameter < 12 mm, cara Manual (untuk bangunan gedung) | E28: Kg | G28: ='HSP PRSPN,STR,ARS'!D248 -> 13579 | H28: =G28*F28 -> 0
B29: e | C29: 2.2.1.1.2 | D29: 1 Kg Penulangan slab untuk BjTP diameter ≥ 12 mm, cara semi mekanis (untuk bangunan gedung) | E29: Kg | G29: ='HSP PRSPN,STR,ARS'!D250 -> 11567 | H29: =G29*F29 -> 0
B30: f | C30: 2.2.1.5.4 | D30: 1 m3 beton mutu sedang f'c 20 Mpa Slump (100 ± 25) mm, agregat maks 19 mm secara semi mekanis | E30: m3 | G30: ='HSP PRSPN,STR,ARS'!D301 -> 24018197 | H30: =G30*F30 -> 0
D31: Pondasi Strauss Pile
C32: 2.2.2.3.6 | D32: Pengeboran 1 m' Lubang bored Pile ø 30 cm pada tanah sedang (manual) | E32: m' | G32: ='HSP PRSPN,STR,ARS'!D376 -> 33000
C33: 2.2.1.1.1 | D33: 1 Kg Penulangan slab untuk BjTP diameter < 12 mm, cara Manual (untuk bangunan gedung) | E33: Kg | G33: ='HSP PRSPN,STR,ARS'!D253 -> 12029
C34: 2.2.1.1.2 | D34: 1 Kg Penulangan slab untuk BjTP diameter ≥ 12 mm, cara semi mekanis (untuk bangunan gedung) | E34: Kg | G34: ='HSP PRSPN,STR,ARS'!D255 -> 12909
C35: 2.2.1.5.4 | D35: 1 m3 beton mutu sedang f'c 20 Mpa Slump (100 ± 25) mm, agregat maks 19 mm secara semi mekanis | E35: m3 | G35: =G30 -> 24018197
B36: JUMLAH I | H36: =SUM(H19:H35) -> 22925065
B37: II. | D37: Pekerjaan Sloff
B38: 1 | C38: 2.2.1.3.2 | D38: (K3) Pemasangan 1 m2 bekisting untuk sloof | E38: m2 | F38: ='[425]BEKISTING SLOFF'!$Q$49 -> 2.49 | G38: ='HSP PRSPN,STR,ARS'!D279 -> 110968 | H38: =G38*F38 -> 276310.32
B39: 2 | C39: 2.2.1.1.3 | D39: 1 Kg Penulangan kolom, balok, ring balk dan sloof untuk BjTP diameter < 12 mm, cara manual (untuk bangunan gedung) | E39: Kg | F39: ='[425]PEMBESIAN SLOFF'!$Q$51 -> 69.72 | G39: =G29 -> 11567 | H39: =G39*F39 -> 806451.24
B40: 3 | C40: 2.2.1.1.4 | D40: 1 Kg Penulangan kolom, balok, ring balk dan sloof untuk BjTP diameter ≥ 12 mm, cara semi mekanis (untuk bangunan gedung) | E40: Kg | F40: ='[425]PEMBESIAN SLOFF'!$Q$50 -> 147.74 | G40: =G28 -> 13579 | H40: =G40*F40 -> 2006161.5
B41: 4 | C41: 2.2.1.5.4 | D41: 1 m3 beton mutu sedang f'c 20 Mpa Slump (100 ± 25) mm, agregat maks 19 mm secara semi mekanis | E41: m3 | F41: ='[425]BETON SLOFF'!$Q$49 -> 1.245 | G41: =G35 -> 24018197 | H41: =G41*F41 -> 29902655
B42: 5 | D42: Membuat 1 m’ sloof praktis beton bertulang (10 x 15) cm | E42: m' | F42: =F62 -> 41.5 | G42: =G62 -> 63591 | H42: =G42*F42 -> 2639026.5
B43: JUMLAH II | H43: =SUM(H38:H42) -> 35630605
B44: III. | D44: Pekerjaan Kolom
...

Sheet HSP PRSPN,STR,ARS
A1: HARGA SATUAN PEKERJAAN
A2: PEKERJAAN PERSIAPAN, STRUKTUR, ARSITEKTUR
A4: No. Mata Pembayaran | B4: Uraian | C4: Satuan | D4: Harga Satuan (Rp)
A6: 1 | B6: PERSIAPAN LAPANGAN/SITE WORK
A7: 1.1 | B7: PEKERJAAN PERSIAPAN
A8: 1.1.1 | B8: Pembuatan pagar proyek | F8: =A8 -> 1.1.1
A9: 1.1.1.1 | B9: Pembuatan 1 m' pagar sementara dari kayu tinggi 2 meter | C9: m' | D9: ='1. AHS PERSIAPAN CK'!G27 -> 2056802
A10: 1.1.1.2 | B10: Pembuatan 1 m' pagar sementara dari seng gelombang rangka kayu tinggi 2 meter | C10: m' | D10: ='1. AHS PERSIAPAN CK'!G51 -> 2034551.2
A11: 1.1.1.3. | B11: Pembuatan 1 m' pagar sementara dari kawat duri tinggi 2meter | C11: m' | D11: ='1. AHS PERSIAPAN CK'!G75 -> 2225878.6
A12: 1.1.1.4. | B12: Pembuatan 1 m' pagar sementara seng gelombang rangka baja L.40.40.4 tinggi pagar 1,8m | C12: m' | D12: ='1. AHS PERSIAPAN CK'!G95 -> 486233.72
A13: 1.1.1.5. | B13: Pembuatan 1 m' pagar BRC Galvanis | C13: m' | D13: ='1. AHS PERSIAPAN CK'!G112 -> 12281.39
A14: 1.1.1.6. | B14: Pemasangan 1 m² panel beton pracetak 50x50x240 cm untuk pagar | C14: m' | D14: ='1. AHS PERSIAPAN CK'!G134 -> 582076
A16: 1.1.2 | B16: Alat dan/atau sarana penunjang
A17: 1.1.2.1 | B17: 1 buah papan nama proyek uk 0,8x1,2 menggunakan multiflex 18mm, frame besi siku dan tiang kayu 8/12 | C17: buah | D17: ='1. AHS PERSIAPAN CK'!G157 -> 670747
A18: 1.1.2.2 | B18: 1 buah papan nama proyek uk 0,6x0,8 menggunakan multiflex 10mm, frame allumunium siku dan tiang kayu 5/7 Printing banner plastik | C18: buah | D18: ='1. AHS PERSIAPAN CK'!G179 -> 278091
A19: 1.1.2.3 | B19: Pembuatan 1m2 kantor sementara/rumah jaga/gudang semen/peralatan lantai plesteran, dinding setengah bata | C19: m2 | D19: ='1. AHS PERSIAPAN CK'!G210 -> 1542750
A20: 1.1.2.4 | B20: Pembuatan 1m2 direksi keet (kantor), los kerja dan gudang | C20: m2 | D20: ='1. AHS PERSIAPAN CK'!G238 -> 1001734.9
A21: 1.1.2.4.b | B21: Pembuatan 1 m² gudang semen dan peralatan | C21: m2 | D21: ='1. AHS PERSIAPAN CK'!G262 -> 643940
A22: 1.1.2.5 | B22: Pembuatan 1m2 Jalan sementara lapis macadam | C22: m2 | D22: ='1. AHS PERSIAPAN CK'!G286 -> 1487680.6
A23: 1.1.2.6 | B23: Pembuatan 1m2 Jalan sementara (jalan tanah) | C23: m2 | D23: ='1. AHS PERSIAPAN CK'!G300 -> 1180940
A24: 1.1.2.7 | B24: Pembuatan 1m2 Jalan sementara (jalan kerikil) | C24: m2 | D24: ='1. AHS PERSIAPAN CK'!G315 -> 1261790
A26: 1.1.3 | B26: Pembersihan dan pengupasan permukaan tanah
A27: 1.1.3.1 | B27: 1 m2 pembersihan dan pengupasan permukaan tanah (stiping) sd tanaman Φ 2 cm | C27: m2 | D27: ='1. AHS PERSIAPAN CK'!G330 -> 22000
A28: 1.1.3.2 | B28: Tebas tebang 1 m2 tanaman/tumbuhan D < 5 cm | C28: m2 | D28: ='1. AHS PERSIAPAN CK'!G344 -> 3960
A29: 1.1.3.3 | B29: Tebas tebang 1 m2 tanaman/tumbuhan D > 5 sd 15cm | C29: m2 | D29: ='1. AHS PERSIAPAN CK'!G358 -> 6600
A30: 1.1.3.4 | B30: Tebas tebang 1 batang pohon/tumbuhan D >15 sd 30 cm | C30: batang | D30: ='1. AHS PERSIAPAN CK'!G373 -> 10952.7
A31: 1.1.3.5 | B31: Tebas tebang 1 batang pohon/tumbuhan D > 30 sd 50 cm | C31: batang | D31: ='1. AHS PERSIAPAN CK'!G388 -> 2271.5
A32: 1.1.3.6 | B32: Tebas tebang 1 batang pohon/tumbuhan D > 50 sd 70 cm (diameter pohon diukur 1m di atas permukaan tanah) | C32: batang | D32: ='1. AHS PERSIAPAN CK'!G403 -> 23320
A33: 1.1.3.7 | B33: Tebas tebang 1 batang pohon/tumbuhan D > 75 cm (diameter pohon diukur 1m di atas permukaan tanah) | C33: batang | D33: ='1. AHS PERSIAPAN CK'!G418 -> 33990
A34: 1.1.3.8 | B34: Gali dan cabut 1 tunggul pohon tanaman keras D > 5 sd 15 cm (termasuk pembuangan tunggul tanpa menutup kembali bekas lubang) | C34: tunggul | D34: ='1. AHS PERSIAPAN CK'!G433 -> 19855
A35: 1.1.3.9 | B35: Gali dan cabut 1 tunggul pohon tanaman keras D > 15 sd 30 cm (termasuk pembuangan tunggul tanpa menutup kembali bekas lubang) | C35: tunggul | D35: ='1. AHS PERSIAPAN CK'!G448 -> 23661
A36: 1.1.3.10 | B36: Gali dan cabut 1 tunggul pohon tanaman keras D > 30 sd 50 cm (termasuk pembuangan tunggul tanpa menutup kembali bekas lubang) | C36: tunggul | D36: ='1. AHS PERSIAPAN CK'!G463 -> 26499
A37: 1.1.3.11 | B37: Gali dan cabut 1 tunggul pohon tanaman keras D > 50 sd 75 cm (termasuk pembuangan tunggul tanpa menutup kembali bekas lubang) | C37: tunggul | D37: ='1. AHS PERSIAPAN CK'!G478 -> 38335
A38: 1.1.3.12 | B38: Gali dan cabut 1 tunggul pohon tanaman keras D > 75 cm (termasuk pembuangan tunggul tanpa menutup kembali bekas lubang) | C38: tunggul | D38: ='1. AHS PERSIAPAN CK'!G493 -> 51073
A39: 1.1.3.13 | B39: Gali dan cabut 1 tunggul pohon tanaman keras D > 5 sd 15 cm (termasuk pembuangan tunggul dengan menutup kembali bekas lubang) | C39: tunggul | D39: ='1. AHS PERSIAPAN CK'!G508 -> 20889
A40: 1.1.3.14 | B40: Gali dan cabut 1 tunggul pohon tanaman keras D > 15 sd 30 cm (termasuk pembuangan tunggul dengan menutup kembali bekas lubang) | C40: tunggul | D40: ='1. AHS PERSIAPAN CK'!G523 -> 34485
A41: 1.1.3.15 | B41: Gali dan cabut 1 tunggul pohon tanaman keras D > 30 sd 50 cm (termasuk pembuangan tunggul dengan menutup kembali bekas lubang) | C41: tunggul | D41: ='1. AHS PERSIAPAN CK'!G538 -> 43109
A42: 1.1.3.16 | B42: Gali dan cabut 1 tunggul pohon tanaman keras D > 50 sd 75 cm (termasuk pembuangan tunggul dengan menutup kembali bekas lubang) | C42: tunggul | D42: ='1. AHS PERSIAPAN CK'!G553 -> 66055
A43: 1.1.3.17 | B43: Gali dan cabut 1 tunggul pohon tanaman keras D > 75 cm (termasuk pembuangan tunggul dengan menutup kembali bekas lubang) | C43: tunggul | D43: ='1. AHS PERSIAPAN CK'!G568 -> 104764
A45: 1.1.4 | B45: Pengukuran dan pasangan Bouwplank
...

Sheet 1. AHS PERSIAPAN CK
A1: 1 | B1: PERSIAPAN LAPANGAN/SITE WORK
A2: 1.1 | B2: PEKERJAAN PERSIAPAN
A3: 1.1.1 | B3: Pembuatan pagar proyek
A4: 1.1.1.1 | B4: Pembuatan 1 m' pagar sementara dari kayu tinggi 2 meter
A5: No | B5: Uraian | C5: Kode | D5: Satuan | E5: Koefisien | F5: Harga Satuan (Rp.) | G5: Jumlah Harga (Rp.)
A6: A | B6: TENAGA
B7: Pekerja | C7: L.01 | D7: OH | E7: 0.6 | F7: =VLOOKUP(B7,'HSD PSPN,STR,ARS'!$C$6:F724,4,FALSE) -> 100000 | G7: =E7*F7 -> 60000
B8: Tukang Kayu | C8: L.02 | D8: OH | E8: 0.2 | F8: =VLOOKUP(B8,'HSD PSPN,STR,ARS'!$C$6:F724,4,FALSE) -> 150000 | G8: =E8*F8 -> 30000
B9: Tukang batu | C9: L.02 | D9: OH | E9: 0.2 | F9: ='HSD PSPN,STR,ARS'!F10 -> 150000 | G9: =E9*F9 -> 30000
B10: Kepala Tukang | C10: L.03 | D10: OH | E10: 0.04 | F10: =VLOOKUP(B10,'HSD PSPN,STR,ARS'!$C$6:F724,4,FALSE) -> 150000 | G10: =E10*F10 -> 6000
B11: Mandor | C11: L.04 | D11: OH | E11: 0.013 | F11: =VLOOKUP(B11,'HSD PSPN,STR,ARS'!$C$6:F724,4,FALSE) -> 200000 | G11: =E11*F11 -> 2600
A12: Jumlah Harga Tenaga Kerja | G12: =SUM(G7:G11) -> 128600
A13: B | B13: BAHAN
B14: kaso kayu5/7 kayu kelas II | D14: m3 | E14: 0.0387 | F14: ='HSD PSPN,STR,ARS'!F718 -> 10000 | G14: =E14*F14 -> 387
B15: Papan Kayu Uk 2/20cm | D15: m3 | E15: 0.0396 | F15: ='HSD PSPN,STR,ARS'!F202 -> 10000 | G15: =E15*F15 -> 396
B16: Paku biasa | D16: Kg | E16: 0.5872 | F16: =VLOOKUP(B16,'HSD PSPN,STR,ARS'!$C$6:F724,4,FALSE) -> 10000 | G16: =E16*F16 -> 5872
B17: Semen Portland | D17: Kg | E17: 26.406 | F17: =VLOOKUP(B17,'HSD PSPN,STR,ARS'!$C$6:F724,4,FALSE) -> 10000 | G17: =E17*F17 -> 264060
B18: Pasir beton | D18: Kg | E18: 61.56 | F18: =VLOOKUP(B18,'HSD PSPN,STR,ARS'!$C$6:F724,4,FALSE) -> 10000 | G18: =E18*F18 -> 615600
B19: Kerikil | D19: Kg | E19: 83.349 | F19: ='HSD PSPN,STR,ARS'!F613 -> 10000 | G19: =E19*F19 -> 833490
B20: Air | D20: Liter | E20: 17.415 | F20: =VLOOKUP(B20,'HSD PSPN,STR,ARS'!$C$6:F724,4,FALSE) -> 1000 | G20: =E20*F20 -> 17415
B21: Residu atau ter | D21: Liter | E21: 0.4 | F21: =VLOOKUP(B21,'HSD PSPN,STR,ARS'!$C$6:F724,4,FALSE) -> 10000 | G21: =E21*F21 -> 4000
A22: Jumlah Harga Bahan | G22: =SUM(G14:G21) -> 1741220
A23: C | B23: PERALATAN
A24: Jumlah Harga Alat | G24: =SUM(G23) -> 0
A25: D | B25: Jumlah Harga Tenaga Kerja, Bahan dan Peralatan (A+B+C) | G25: =SUM(G7:G24)/2 -> 1869820
A26: E | B26: Biaya Umum dan Keuntungan (10% - 15%) x D | F26: 0.1 | G26: =G25*F26 -> 186982
A27: F | B27: Harga Satuan Pekerjaan (D+E) | G27: =G25+G26 -> 2056802
A29: A.1.1.1.2 | B29: Pembuatan 1 m' pagar sementara dari seng gelombang rangka kayu tinggi 2 meter
A30: No | B30: Uraian | C30: Kode | D30: Satuan | E30: Koefisien | F30: Harga Satuan (Rp.) | G30: Jumlah Harga (Rp.)
A31: A | B31: TENAGA
B32: Pekerja | C32: L.01 | D32: OH | E32: 0.25 | F32: =VLOOKUP(B32,'HSD PSPN,STR,ARS'!$C$6:F724,4,FALSE) -> 100000 | G32: =E32*F32 -> 25000
B33: Tukang Kayu | C33: L.02 | D33: OH | E33: 0.125 | F33: =VLOOKUP(B33,'HSD PSPN,STR,ARS'!$C$6:F724,4,FALSE) -> 150000 | G33: =E33*F33 -> 18750
B34: Tukang batu | C34: L.02 | D34: OH | E34: 0.125 | F34: =VLOOKUP(B34,'HSD PSPN,STR,ARS'!$C$6:F724,4,FALSE) -> 150000 | G34: =E34*F34 -> 18750
B35: Kepala Tukang | C35: L.03 | D35: OH | E35: 0.25 | F35: =VLOOKUP(B35,'HSD PSPN,STR,ARS'!$C$6:F724,4,FALSE) -> 150000 | G35: =E35*F35 -> 37500
B36: Mandor | C36: L.04 | D36: OH | E36: 0.008 | F36: =VLOOKUP(B36,'HSD PSPN,STR,ARS'!$C$6:F724,4,FALSE) -> 200000 | G36: =E36*F36 -> 1600
A37: Jumlah Harga Tenaga Kerja | G37: =SUM(G32:G36) -> 101600
A38: B | B38: BAHAN
B39: Kayu kaso 5/7 | D39: m3 | E39: 0.0031 | F39: =VLOOKUP(B39,'HSD PSPN,STR,ARS'!$C$6:F724,4,FALSE) -> 10000 | G39: =E39*F39 -> 31
B40: Seng gelombang | D40: Lbr | E40: 1.3125 | F40: =VLOOKUP(B40,'HSD PSPN,STR,ARS'!$C$6:F724,4,FALSE) -> 10000 | G40: =E40*F40 -> 13125
B41: Paku biasa | D41: Kg | E41: 0.4271 | F41: =VLOOKUP(B41,'HSD PSPN,STR,ARS'!$C$6:F724,4,FALSE) -> 10000 | G41: =E41*F41 -> 4271
...

Sheet 2. AHS STUKTUR CK
A1: 2 | B1: PEKERJAAN STRUKTUR
A2: 2.1 | B2: PEKERJAAN RANGKA ATAP
A3: 2.1.1 | B3: Rangka Atap Baja Ringan
A4: 2.1.1.1 | B4: Pemasangan 1 m² atap pelana rangka atap baja ringan canai dingin profil C75
A5: No | B5: Uraian | C5: Kode | D5: Satuan | E5: Koefisien | F5: Harga Satuan (Rp.) | G5: Jumlah Harga (Rp.)
A6: A | B6: TENAGA
B7: Pekerja | C7: L.01 | D7: OH | E7: 0.1014 | F7: =VLOOKUP(B7,'HSD PSPN,STR,ARS'!$C$6:F724,4,FALSE) -> 100000 | G7: =E7*F7 -> 10140
B8: Tukang Besi | C8: L.02 | D8: OH | E8: 0.0169 | F8: =VLOOKUP(B8,'HSD PSPN,STR,ARS'!$C$6:F724,4,FALSE) -> 150000 | G8: =E8*F8 -> 2535
B9: Kepala Tukang | C9: L.03 | D9: OH | E9: 0.0017 | F9: =VLOOKUP(B9,'HSD PSPN,STR,ARS'!$C$6:F724,4,FALSE) -> 150000 | G9: =E9*F9 -> 255
B10: Mandor | C10: L.04 | D10: OH | E10: 0.0006 | F10: =VLOOKUP(B10,'HSD PSPN,STR,ARS'!$C$6:F724,4,FALSE) -> 200000 | G10: =E10*F10 -> 120
A11: Jumlah Harga Tenaga Kerja | G11: =SUM(G7:G10) -> 13050
A12: B | B12: BAHAN
B13: Baja Ringan C75, t 1mm (Batang Utama) | D13: btg | E13: 0.6137 | F13: =VLOOKUP(B13,'HSD PSPN,STR,ARS'!$C$6:F727,4,FALSE) -> 10000 | G13: =E13*F13 -> 6137
B14: Baja Ringan C75, t 0,75 mm (Batang Pengaku) | D14: btg | E14: 0.5016 | F14: =VLOOKUP(B14,'HSD PSPN,STR,ARS'!$C$6:F728,4,FALSE) -> 10000 | G14: =E14*F14 -> 5016
B15: Baja Ringan C75 t a mm (L Bracet) | D15: btg | E15: 0.0113 | F15: =VLOOKUP(B15,'HSD PSPN,STR,ARS'!$C$6:F729,4,FALSE) -> 10000 | G15: =E15*F15 -> 113
B16: Dynabolt dia. 12x120mm | D16: buah | E16: 0.6429 | F16: =VLOOKUP(B16,'HSD PSPN,STR,ARS'!$C$6:F730,4,FALSE) -> 10000 | G16: =E16*F16 -> 6429
B17: Self drilling screw dia 6x20mm (main truss screw) | D17: buah | E17: 15.75 | F17: =VLOOKUP(B17,'HSD PSPN,STR,ARS'!$C$6:F731,4,FALSE) -> 10000 | G17: =E17*F17 -> 157500
B18: Reng/roof bottom RT 35 t=0,45 mm | D18: btg | E18: 0.3357 | F18: =VLOOKUP(B18,'HSD PSPN,STR,ARS'!$C$6:F732,4,FALSE) -> 10000 | G18: =E18*F18 -> 3357
B19: Self drilling screw dia 4x16mm (Roof Bottom Screw) | D19: buah | E19: 3 | F19: =VLOOKUP(B19,'HSD PSPN,STR,ARS'!$C$6:F733,4,FALSE) -> 10000 | G19: =E19*F19 -> 30000
A20: Jumlah Harga Bahan | G20: =SUM(G13:G19) -> 208552
A21: C | B21: PERALATAN
B22: Mesin Bor Listrik | D22: jam | E22: 0.3726 | F22: =VLOOKUP(B22,'HSD PSPN,STR,ARS'!$C$6:F736,4,FALSE) -> 10000 | G22: =E22*F22 -> 3726
A23: Jumlah Harga Alat | G23: =G22 -> 3726
A24: D | B24: Jumlah Harga Tenaga Kerja, Bahan dan Peralatan (A+B+C) | G24: =SUM(G7:G23)/2 -> 225328
A25: E | B25: Biaya Umum dan Keuntungan (10% - 15%) x D | F25: 0.1 | G25: =G24*F25 -> 22532.8
A26: F | B26: Harga Satuan Pekerjaan (D+E) | G26: =ROUNDDOWN(G24+G25,0) -> 247860
A28: 2.1.1.2 | B28: Pemasangan 1 m² atap jurai/limasan rangka atap baja ringan canai dingin profil C75
A29: No | B29: Uraian | C29: Kode | D29: Satuan | E29: Koefisien | F29: Harga Satuan (Rp.) | G29: Jumlah Harga (Rp.)
A30: A | B30: TENAGA
B31: Pekerja | C31: L.01 | D31: OH | E31: 0.7604 | F31: =VLOOKUP(B31,'HSD PSPN,STR,ARS'!$C$6:F724,4,FALSE) -> 100000 | G31: =E31*F31 -> 76040
B32: Tukang Besi | C32: L.02 | D32: OH | E32: 0.7604 | F32: =VLOOKUP(B32,'HSD PSPN,STR,ARS'!$C$6:F724,4,FALSE) -> 150000 | G32: =E32*F32 -> 114060
B33: Kepala Tukang | C33: L.03 | D33: OH | E33: 0.076 | F33: =VLOOKUP(B33,'HSD PSPN,STR,ARS'!$C$6:F724,4,FALSE) -> 150000 | G33: =E33*F33 -> 11400
B34: Mandor | C34: L.04 | D34: OH | E34: 0.0253 | F34: =VLOOKUP(B34,'HSD PSPN,STR,ARS'!$C$6:F724,4,FALSE) -> 200000 | G34: =E34*F34 -> 5060
A35: Jumlah Harga Tenaga Kerja | G35: =SUM(G31:G34) -> 206560
A36: B | B36: BAHAN
B37: Baja ringan canai dingin C75 | D37: btg | E37: 0.9603 | F37: =VLOOKUP(B37,'HSD PSPN,STR,ARS'!$C$6:F724,4,FALSE) -> 10000 | G37: =E37*F37 -> 9603
A38: Jumlah Harga Bahan | G38: =SUM(G37) -> 9603
A39: C | B39: PERALATAN
A41: Jumlah Harga Alat | G41: =G40 -> 0
A42: D | B42: Jumlah Harga Tenaga Kerja, Bahan dan Peralatan (A+B+C) | G42: =SUM(G31:G41)/2 -> 216163
...

Sheet 3. AHS ARSITEKTURAL
A1: 3 | B1: PEKERJAAN ARSITEKTUR
A2: 3.1 | B2: PEKERJAAN PENUTUP ATAP
A3: 3.1.1 | B3: ATAP GENTENG
A4: 3.1.1.1 | B4: Pemasangan 1 m2 Atap Genteng Palentong Kecil
A5: No | B5: Uraian | C5: Kode | D5: Satuan | E5: Koefisien | F5: Harga Satuan (Rp.) | G5: Jumlah Harga (Rp.)
A6: A | B6: TENAGA KERJA
A7: 1 | B7: Pekerja | C7: L.01 | D7: OH | E7: 0,1500 | F7: =VLOOKUP(B7,'HSD PSPN,STR,ARS'!$C$6:F724,4,FALSE) -> 100000 | G7: =F7*E7 -> 15000
A8: 2 | B8: Tukang Kayu | C8: L.02 | D8: OH | E8: 0,0750 | F8: =VLOOKUP(B8,'HSD PSPN,STR,ARS'!$C$6:F724,4,FALSE) -> 150000 | G8: =F8*E8 -> 11250
A9: 3 | B9: Kepala Tukang | C9: L.03 | D9: OH | E9: 0,0075 | F9: =VLOOKUP(B9,'HSD PSPN,STR,ARS'!$C$6:F724,4,FALSE) -> 150000 | G9: =F9*E9 -> 1125
A10: 4 | B10: Mandor | C10: L.04 | D10: OH | E10: 0.0025 | F10: =VLOOKUP(B10,'HSD PSPN,STR,ARS'!$C$6:F724,4,FALSE) -> 200000 | G10: =F10*E10 -> 500
A11: Jumlah Harga Tenaga Kerja | G11: =SUM(G6:G10) -> 27875
A12: B | B12: BAHAN
A13: 1 | B13: Genteng Palentong kecil | D13: buah | E13: 25,00 | F13: =VLOOKUP(B13,'HSD PSPN,STR,ARS'!$C$6:F724,4,FALSE) -> 10000 | G13: =F13*E13 -> 250000
A14: Jumlah Harga Bahan | G14: =SUM(G13) -> 250000
A15: C | B15: PERALATAN
A17: Jumlah Harga Alat | G17: =SUM(G15:G16) -> 0
A18: D | B18: Jumlah Harga Tenaga Kerja, Bahan dan Peralatan (A+B+C) | G18: =SUM(G6:G17)/2 -> 277875
A19: E | B19: Biaya Umum dan Keuntungan (10% - 15%) x D | F19: 0.1 | G19: =G18*F19 -> 27787.5
A20: F | B20: Harga Satuan Pekerjaan (D+E) | G20: =ROUNDDOWN(G18+G19,0) -> 305662
A22: 3.1.1.2 | B22: Pemasangan 1 m2 Atap Genteng Kodok Glazuur
A23: No | B23: Uraian | C23: Kode | D23: Satuan | E23: Koefisien | F23: Harga Satuan (Rp) | G23: Jumlah Harga (Rp)
A24: A | B24: TENAGA KERJA
A25: 1 | B25: Pekerja | C25: L.01 | D25: OH | E25: 0,1500 | F25: =VLOOKUP(B25,'HSD PSPN,STR,ARS'!$C$6:F724,4,FALSE) -> 100000 | G25: =F25*E25 -> 15000
A26: 2 | B26: Tukang Kayu | C26: L.02 | D26: OH | E26: 0,0750 | F26: =VLOOKUP(B26,'HSD PSPN,STR,ARS'!$C$6:F724,4,FALSE) -> 150000 | G26: =F26*E26 -> 11250
A27: 3 | B27: Kepala Tukang | C27: L.03 | D27: OH | E27: 0,0075 | F27: =VLOOKUP(B27,'HSD PSPN,STR,ARS'!$C$6:F724,4,FALSE) -> 150000 | G27: =F27*E27 -> 1125
A28: 4 | B28: Mandor | C28: L.04 | D28: OH | E28: 0,0025 | F28: =VLOOKUP(B28,'HSD PSPN,STR,ARS'!$C$6:F724,4,FALSE) -> 200000 | G28: =F28*E28 -> 500
A29: Jumlah Harga Tenaga Kerja | G29: =SUM(G24:G28) -> 27875
A30: B | B30: BAHAN
A31: 1 | B31: Genteng Kodok | D31: buah | E31: 25,00 | F31: =VLOOKUP(B31,'HSD PSPN,STR,ARS'!$C$6:F724,4,FALSE) -> 10000 | G31: =F31*E31 -> 250000
A32: Jumlah Harga Bahan | G32: =SUM(G31) -> 250000
A33: C | B33: PERALATAN
G34: =F34*E34 -> 0
A35: Jumlah Harga Alat | G35: =SUM(G33:G34) -> 0
A36: D | B36: Jumlah Harga Tenaga Kerja, Bahan dan Peralatan (A+B+C) | G36: =SUM(G24:G35)/2 -> 277875
A37: E | B37: Biaya Umum dan Keuntungan (10% - 15%) x D | F37: 0.1 | G37: =G36*F37 -> 27787.5
A38: F | B38: Harga Satuan Pekerjaan (D+E) | G38: =ROUNDDOWN(G36+G37,0) -> 305662
A40: 3.1.1.3 | B40: Pemasangan 1 m2 Atap Genteng Palentong Besar
A41: No | B41: Uraian | C41: Kode | D41: Satuan | E41: Koefisien | F41: Harga Satuan (Rp) | G41: Jumlah Harga (Rp)
A42: A | B42: TENAGA KERJA
A43: 1 | B43: Pekerja | C43: L.01 | D43: OH | E43: 0,1500 | F43: =VLOOKUP(B43,'HSD PSPN,STR,ARS'!$C$6:F724,4,FALSE) -> 100000 | G43: =F43*E43 -> 15000
...

Sheet HSD PSPN,STR,ARS
B1: HARGA SATUAN DASAR PERSIAPAN, STRUKTUR, ARSITEKTUR
B2: UPAH TENAGA KERJA, BAHAN DAN PERALATAN
B4: NO. | C4: URAIAN | D4: KODE | E4: SATUAN | F4: HARGA | G4: KET.
B5: A. | C5: UPAH TENAGA KERJA
B6: 1 | C6: Kepala Tukang | E6: OH | F6: 150000
B7: 2 | C7: Tukang | E7: OH | F7: 150000
B8: 3 | C8: Tukang Aluminium | E8: OH | F8: =+$F$7 -> 150000
B9: 4 | C9: Tukang batu | E9: OH | F9: =+$F$7 -> 150000
B10: 5 | C10: Tukang batu/tembok | E10: OH | F10: =+$F$7 -> 150000
B11: 6 | C11: Tukang Besi | E11: OH | F11: =+$F$7 -> 150000
B12: 7 | C12: Tukang Besi/ Besi Beton | E12: OH | F12: 100000
B13: 8 | C13: Tukang Cat | E13: OH | F13: =+$F$7 -> 150000
B14: 9 | C14: Tukang Cat/Pelitur | E14: OH | F14: =+$F$7 -> 150000
B15: 10 | C15: Tukang Ereksi | E15: OH | F15: =+$F$7 -> 150000
B16: 11 | C16: Tukang Kayu | E16: OH | F16: =+$F$7 -> 150000
B17: 12 | C17: Tukang Las | E17: OH | F17: =+$F$7 -> 150000
B18: 13 | C18: Tukang Las Konstruksi | E18: OH | F18: =+$F$7 -> 150000
B19: 14 | C19: Tukang Pipa | E19: OH | F19: =+$F$7 -> 150000
B20: 15 | C20: Tukang Listrik | E20: OH | F20: =+$F$7 -> 150000
B21: 16 | C21: Tukang Kaca | E21: OH | F21: =+$F$7 -> 150000
B22: 17 | C22: Tukang vibrator | E22: OH | F22: =+$F$7 -> 150000
B23: 18 | C23: Tukang penganyam bronjong | E23: OH | F23: =F22 -> 150000
B24: 19 | C24: Pekerja | E24: OH | F24: 100000
B25: 20 | C25: Mandor | E25: OH | F25: 200000
B26: 21 | C26: Operator Alat Berat | E26: OH | F26: 200000
B27: 22 | C27: Operator Alat Pipa | E27: OH | F27: =F26 -> 200000
B28: 23 | C28: Operator Crane | E28: OH | F28: =+F27 -> 200000
B29: 24 | C29: Pembantu Operator Crane | E29: OH | F29: 150000
B30: 25 | C30: Juru ukur | E30: OH | F30: 200000
B31: 26 | C31: Pembantu juru ukur | E31: OH | F31: =F23 -> 150000
B32: 28 | C32: Tenaga terampil operator | E32: OH | F32: =F28 -> 200000
B33: 29 | C33: Tanaga ahli pratama | E33: OH | F33: =250000 -> 250000
B34: 30 | C34: Tukang Las geotestile | E34: OH | F34: =F23 -> 150000
B35: B. | C35: BAHAN
B37: 1 | C37: Agg pengunci | E37: m³ | F37: 300000
B38: 2 | C38: Agg penutup | E38: kg | F38: 8500
B39: 3 | C39: Agg pokok | E39: m³ | F39: 200000
B40: 4 | C40: Air | E40: Liter | F40: 1000
B41: 5 | C41: Alang-alang | E41: ikat | F41: 10000
B42: 6 | C42: Alat penyambung balok Δ 28 cm | E42: buah | F42: 10000
...

Sheet BACK UP DATA
A7: No | B7: Uraian | C7: Panjang | D7: Lebar | E7: Tinggi | F7: Luas | G7: Jlh Unit | H7: Volume | I7: Total Volume | J7: Satuan | K7: Ket
A9: A. | B9: PEKERJAAN PERSIAPAN
A10: 1 | B10: Pembersihan Lokasi | I10: 1 Ls
A11: 2 | B11: Pengukuran Dan Pemasangan Bowplank | I11: 1 Ls
A12: 3 | B12: Direksiket atau Barak Kerja | I12: 1 Ls
A13: 4 | B13: Air Dan Listrik Kerja | I13: 1 Ls
A14: 5 | B14: Keamanan Dan P3K | I14: 1 Ls
A16: B. | B16: PEKERJAAN TANAH
A17: 1 | B17: Galian Tanah Pondasi
B18: - Pondasi Tapak | C18: 2 | D18: 2 | E18: 1.7 | G18: 50 | H18: =(C18*D18*E18)*G18 -> 340
B19: - Pondasi Menerus
B20: Panjang As 1 | C20: 2
B21: Panjang As 2=3=4=5 | C21: =2*11*4-(2) -> 86
B22: Panjang As A s/d L | C22: =2*12*2 -> 48
B23: Panjang As A-B (KM) | C23: =1.1*2 -> 2.2
B24: Panjang As K-L (KM) | C24: =1.1*2 -> 2.2
B25: Panjang As A-B (KM) | C25: =3.1*2 -> 6.2
C26: 1.1
B27: Panjang As K-L (KM) | C27: =3.1*2 -> 6.2
C28: 1.1
B29: total | C29: =SUM(C20:C28) -> 155
C30: =+C29 -> 155 | D30: 0.9 | E30: 0.75 | H30: =C30*D30*E30 -> 104.625 | I30: =+H18+H30 -> 444.625 | J30: M3
A31: 2 | B31: Urugan Kembali
B32: Pondasi Tapak | C32: 2 | D32: 2 | E32: 1.5 | G32: 50 | H32: =+C32*D32*E32*G32 -> 300
B33: Pondasi Menerus | C33: =+C29 -> 155 | D33: 0.35 | E33: 0.6 | H33: =+C33*D33*E33 -> 32.55
B34: Pengurangan Beton Tapak | C34: 1.8 | D34: 1.8 | E34: -0.4 | G34: 50 | H34: =+C34*D34*E34*G34 -> -64.8
B35: Pengurangan Pondasi Menerus | C35: 0.7 | D35: =+(0.7+0.4)/2 -> 0.55 | E35: -0.6 | G35: 48 | H35: =+C35*D35*E35*G35 -> -11.088
C36: 0.6 | D36: =+(0.7+0.4)/2 -> 0.55 | E36: -0.6 | G36: 52 | H36: =+C36*D36*E36*G36 -> -10.296
B37: Pengurangan pasir alas dan batu kosong | C37: 0.7 | D37: 0.9 | E37: -0.15 | G37: 48 | H37: =+C37*D37*E37*G37 -> -4.536
C38: 0.6 | D38: 0.9 | E38: -0.15 | G38: 52 | H38: =+C38*D38*E38*G38 -> -4.212
I39: =SUM(H32:H39) -> 237.618 | J39: M3
A40: 3 | B40: Urugan Pasir
B41: Pondasi tapak | C41: 2 | D41: 2 | E41: 0.05 | G41: 50 | H41: =+(C41*D41*E41)*G41 -> 10
B42: Pondasi Menerus
B43: Panjang As 1 | C43: 3.7
B44: Panjang As 2=3=4=5 | C44: =3.7*11*4-(2) -> 160.8
B45: Panjang As A s/d L | C45: =3.6*12*2 -> 86.4
B46: Panjang As A-B (KM) | C46: =1.1*2 -> 2.2
B47: Panjang As K-L (KM) | C47: =1.1*2 -> 2.2
B48: Panjang As A-B (KM) | C48: =3.1*2 -> 6.2
...

Sheet hit besi
A1: BACK UP DATA
A2: PEKERJAAN | C2: : PEMBANGUNAN ASRAMA PUTRI
A3: LOKASI | C3: : BANDA ACEH
A4: TAHUN | C4: : 2019 | S4: 32
A5: PEKERJAAN LANTAI I | S5: 32
A6: PEKERJAAN PEMBESIAN | S6: 22
A7: KOLOM 30 X 40 ( PEDESTAL) | S7: 22
A8: No. | B8: Uraian | E8: P | F8: JLH | G8: JLH | H8: Berat/ Dia Besi | K8: UNIT | L8: BERAT BESI | N8: SATUAN | S8: 14
F9: Sengkang | G9: POTONG | H9: 8 | I9: 13 | J9: 14 | L9: POLOS | M9: ULIR | S9: =SUM(S4:S8) -> 122
A11: B.I.1 | B11: Tinggi Kolom | E11: =+O11 -> 1.5 | O11: 1.5
B12: Besi Polos | D12: Type 1 | E12: =+R12 -> 1.22 | F12: 15 | G12: 1 | H12: =+((H9/1000)^2)*6165 -> 0.39456 | K12: 50 | L12: =+E12*F12*G12*H12*K12 -> 361.0224 | O12: =E11/0.1 -> 15 | P12: 0.32 | Q12: 0.22 | R12: =+P12*2+Q12*2+0.07*2 -> 1.22
D13: Type II | E13: =+R13 -> 1.26 | G13: 2 | H13: 0.6165 | L13: =+E13*F13*G13*H13*K13 -> 0 | O13: =+E11/0.2 -> 7.5 | P13: 0.25 | R13: =2*P12+2*P13+2*6*0.01 -> 1.26
D14: Type III | E14: =+R14 -> 1.98 | G14: 1 | H14: 0.6165 | O14: =+E11/0.5 -> 3 | P14: 0.25 | R14: 1.98
B15: Besi Ulir | E15: =+O15 -> 3.044 | G15: 10 | J15: =+((J9/1000)^2)*6165 -> 1.20834 | K15: 50 | M15: =+E15*G15*J15*K15 -> 1839.0935 | O15: =+O11+(6*0.014)+0.5+0.4+(40*0.014) -> 3.044
E18: JUMLAH | L18: =SUM(L12:L17) -> 361.0224 | M18: =SUM(M12:M17) -> 1839.0935 | N18: Kg
P19: =0.785*22*22*22 -> 8358.68 | R19: =50*140 -> 7000 | S19: =+P19/100 -> 83.5868 | T19: =+S19/R19 -> 0.011940971
A21: SLOOF (30X40)
A22: No. | B22: Uraian | E22: P | F22: JLH | G22: JLH | H22: Berat/ Dia Besi | K22: UNIT | L22: BERAT BESI | N22: SATUAN
F23: Sengkang | G23: POTONG | H23: 8 | I23: 12 | J23: 14 | L23: POLOS | M23: ULIR
B24: As 2=3=4=5 | E24: 44 | O24: 0.014 | P24: 0.012
B25: Tulangan Atas (utama ) | E25: =+O25 -> 44.74 | G25: 4 | J25: =+(14/1000)^2*6165 -> 1.20834 | K25: 1 | M25: =+E25*G25*J25*K25 -> 216.24453 | O25: =44+2*0.3+2*0.07 -> 44.74 | P25: =+O25-0.5 -> 44.24
B26: Tulangan Bagi | E26: =+O26 -> 44.1 | G26: 2 | I26: =+(12/1000)^2*6165 -> 0.88776 | K26: 1 | L26: =+E26*G26*I26*K26 -> 78.300432 | O26: =44+2*0.05 -> 44.1
B27: Tulangan Bawah (utama ) | E27: =+O27 -> 44.74 | G27: 4 | J27: =+(14/1000)^2*6165 -> 1.20834 | K27: 1 | M27: =+E27*G27*J27*K27 -> 216.24453 | O27: =44+2*0.3+2*0.07 -> 44.74
B28: Tulangan Tromol (Extra) both end | E28: =+O28 -> 2.7 | G28: 2 | J28: =+(14/1000)^2*6165 -> 1.20834 | K28: 11 | M28: =+E28*G28*J28*K28 -> 71.775396 | O28: =2+2*20*0.014+0.07*2 -> 2.7
B29: Tulangan Tromol (Extra) middle | E29: =+O29 -> 2.7 | G29: 2 | J29: =+(14/1000)^2*6165 -> 1.20834 | K29: 11 | M29: =+E29*G29*J29*K29 -> 71.775396 | O29: =2+2*20*0.014+0.07*2 -> 2.7
B30: Panjang Penyaluran tul utama | E30: =40*0.014 -> 0.56 | J30: =+(14/1000)^2*6165 -> 1.20834 | K30: 4 | M30: =+E30*J30*K30 -> 2.7066816 | O30: =2.5+2*20*O24 -> 3.06
B31: Panjang Penyaluran tul bagi | E31: =40*0.012 -> 0.48 | I31: =+(12/1000)^2*6165 -> 0.88776 | K31: 4 | L31: =+E31*I31*K31 -> 1.7044992
B32: Sengkang | E32: =+O32 -> 1.36 | F32: 441 | H32: =+(8/1000)^2*6165 -> 0.39456 | K32: 1 | L32: =+E32*F32*H32*K32 -> 236.64131 | O32: =+(0.24+0.34+0.1)*2 -> 1.36 | R32: =+E24/0.1 -> 440
B33: Jumlah As (A) | L33: =SUM(L25:L32) -> 316.64624 | M33: =SUM(M25:M32) -> 578.74653 | N33: Kg | R33: =#REF!/0.25 -> #REF!
B34: Sub Jumlah | K34: 4 | L34: =+L33*K34 -> 1266.5849 | M34: =+M33*K34 -> 2314.9861 | N34: Kg
A36: SLOOF (30X40)
A37: No. | B37: Uraian | E37: P | F37: JLH | G37: JLH | H37: Berat/ Dia Besi | K37: UNIT | L37: BERAT BESI | N37: SATUAN
F38: Sengkang | G38: POTONG | H38: 8 | I38: 12 | J38: 14 | L38: POLOS | M38: ULIR
B39: As A=....As=L | E39: 10 | O39: 0.014 | P39: 0.012
B40: Tulangan Atas (utama ) | E40: =+O40 -> 10.84 | G40: 4 | J40: =+(14/1000)^2*6165 -> 1.20834 | K40: 1 | M40: =+E40*G40*J40*K40 -> 52.393622 | O40: =10+2*0.15+2*0.2+2*0.07 -> 10.84 | P40: =+O40-0.5 -> 10.34
B41: Tulangan Bagi | E41: =+O41 -> 10.4 | G41: 2 | I41: =+(12/1000)^2*6165 -> 0.88776 | K41: 1 | L41: =+E41*G41*I41*K41 -> 18.465408 | O41: =10.3+2*0.05 -> 10.4
B42: Tulangan Bawah (utama ) | E42: =+O42 -> 10.84 | G42: 4 | J42: =+(14/1000)^2*6165 -> 1.20834 | K42: 1 | M42: =+E42*G42*J42*K42 -> 52.393622 | O42: =+O40 -> 10.84
B43: Tulangan Tromol (Extra) both end | E43: =+O43 -> 2.7 | G43: 2 | J43: =+(14/1000)^2*6165 -> 1.20834 | K43: 3 | M43: =+E43*G43*J43*K43 -> 19.575108 | O43: =2+2*20*0.014+0.07*2 -> 2.7
B44: Tulangan Tromol (Extra) middle | E44: =+O44 -> 2.7 | G44: 2 | J44: =+(14/1000)^2*6165 -> 1.20834 | K44: 2 | M44: =+E44*G44*J44*K44 -> 13.050072 | O44: =2+2*0.07+2*20*0.014 -> 2.7
B45: Panjang Penyaluran tul utama | E45: =40*0.014 -> 0.56 | J45: =+(14/1000)^2*6165 -> 1.20834 | M45: =+E45*J45*K45 -> 0 | O45: =2.5+2*20*O39 -> 3.06
...

Sheet PERHITUNGAN K-3
C3: RINCIAN MATA PEMBAYARAN PENYELENGGARAAN
C4: KESELEMATAN DAN KESELAMATAN KERJA (K-3) | R4: =0.008*1884000000 -> 15072000
C10: NO | D10: URAIAN PEKERJAAN | I10: SATUAN | J10: VOLUME | K10: WAKTU | L10: HARGA SATUAN | M10: TOTAL HARGA | N10: PPN 10% | O10: JUMLAH HARGA SETELAH PAJAK
L11: (RP.) | M11: (RP.)
C12: A. | D12: ALAT PELINDUNG KERJA
C13: 1 | D13: Tali Keselamatan (Life Line); | I13: Ls | J13: 1 | K13: 1 | L13: 600000 | M13: =J13*K13*L13 -> 600000 | N13: 0.1
N14: 0.1
C15: B. | D15: ALAT PELINDUNG DIRI
C16: 1 | D16: Helm Pelindung | I16: Buah | J16: 5 | K16: 1 | L16: 75000 | M16: =J16*K16*L16 -> 375000
C17: =C16+1 -> 2 | D17: Sarung Tangan | I17: Set | J17: 5 | K17: 1 | L17: 65000 | M17: =J17*K17*L17 -> 325000
D18: Rumpi | I18: Buah | J18: 3 | K18: 3 | M18: =J18*K18*L18 -> 0
C19: 3 | D19: Sepatu Keselamatan | I19: Set | J19: 5 | K19: 1 | L19: 300000 | M19: =J19*K19*L19 -> 1500000
C20: =C19+1 -> 4 | D20: Masker | I20: Buah | J20: 5 | K20: 1 | L20: 5000 | M20: =J20*K20*L20 -> 25000
C22: C. | D22: FASILITAS SARANA KESEHATAN
C23: 1 | D23: Peralatan P3K (Kotak P3K, Tandu, Tabung Oksigen, Obat Luka, Perban, dll) | I23: Ls | J23: 1 | K23: 1 | L23: 1000000 | M23: =J23*K23*L23 -> 1000000
C25: D. | D25: ASURANSI DAN PERIJINAN
C26: 1 | D26: BPJS Ketenagakerjaan dan Kesehatan Kerja; (BERDASARKAN KEPMENAKER NOMOR : KEP-196/MEN/1999, untuk tenaga harian proyek | I26: Ls | J26: 1 | K26: 1 | L26: =M47 -> 897702.5 | M26: =J26*K26*L26 -> 897702.5 | N26: 0.1 | R26: =240/30 -> 8
C28: E. | D28: RAMBU-RAMBU
C29: 1 | D29: Rambu Larangan; | I29: Bh | J29: 1 | K29: 1 | L29: 100000 | M29: =J29*K29*L29 -> 100000
C30: 2 | D30: Rambu Peringatan; | I30: Bh | J30: 1 | K30: 1 | L30: 100000 | M30: =J30*K30*L30 -> 100000
L33: JUMLAH TOTAL | M33: =SUM(M13:P31) -> 4922702.8 | R33: PAGU | S33: 706500000
L34: DIBULATKAN | M34: =ROUNDDOWN(M33,-3) -> 4922000 | S34: =0.008*S33 -> 5652000
C38: PERHITUNGAN IURAN BPJS KETENAGAAN KERJAAN SEKTOR JASA KONSTRUKSI
C40: NO | D40: RANGE NILAI PROYEK | I40: RANGE NILAI YANG DIHITUNG | K40: % PREMI | M40: PREMI | N40: KETERANGAN
C42: 1 | D42: 1000000 | F42: S/D | G42: 100000000 | I42: = | K42: 0.0024 | M42: =K42*J42 -> 0
C43: 2 | D43: =G42 -> 100000000 | F43: S/D | G43: 500000000 | I43: = | J43: 472475000 | K43: 0.0019 | M43: =K43*J43 -> 897702.5
C44: 3 | D44: =G43 -> 500000000 | F44: S/D | G44: 1000000000 | I44: = | K44: 0.0015 | M44: =K44*J44 -> 0 | S44: =J43*2% -> 9449500
C45: 4 | D45: =G44 -> 1000000000 | F45: S/D | G45: 5000000000 | I45: = | K45: 0.0012 | M45: =K45*J45 -> 0 | R45: 1000000000
C46: 5 | F46: > | G46: =G45 -> 5000000000 | I46: = | K46: 0.001 | M46: =K46*J46 -> 0
C47: TOTAL PREMI YANG HARUS DI BAYAR | M47: =SUM(M42:M46) -> 897702.5
J61: =J43+J44 -> 472475000
