Workbook

Sheet INFORMASI
A1: AHS PEKERJAAN LANSEKAP
A2: DIBUAT BERDASARKAN SURAT EDARAN BINA KONSTRUKSI NO. 182 TAHUN 2025
A5: ANALISA HARGA SATUAN INI
A6: TERDIRI DARI HSP (HARGA SATUAN PEKERJAAN), AHS (ANALISA HARGA SATUAN), HSD (HARGA SATUAN DASAR) UPAH BAHAN ALAT
A8: Untuk pembuatan RAB harap diperhatikan penjumlahan dalam analisa karena bisa berubah setiap program excel sehingga mengakibatkan ketidak validan perhitungan
B11: BACA DULU :
B12: 1. Program ini terdiri dari HSP (Harga Satuan Pekerjaan), AHS (Analisa harga satuan), HSD (Harga Satuan Dasar) Upah dan Bahan
B13: 2. Cukup merubah harga HSD maka AHS dan HSP akan langsung berubah menyesuaikan
B14: 3. AHS ini dibuat berdasarkan SE Bina Konstruksi No. 182 tahun 2025, sebagai update dari SE BK No. 30 Tahun 2025
B15: 4. Untuk membuat RAB, cukup cari pekerjaan yang sesuai di HSP, lalu dari HSP cek AHS, dari AHS kemudian rubah harga bahan di HSD, otomatis AHS dan HSP akan berubah menyesuaikan, harga pada HSP bisa digunakan untuk RAB
B16: 5. Harga default untuk Bahan dan alat adalah Rp.10.000 yang bisa diubah sesuai harga setempat

Sheet HSP
A1: 4 PEKERJAAN LANSEKAP
A2: HARGA SATUAN PEKERJAAN
A4: No. Mata Pembayaran | B4: Uraian | C4: Satuan | D4: Harga Satuan (Rp)
A5: 4 | B5: PEKERJAAN LANSEKAP
A6: 4.1 | B6: PEKERJAAN PENANAMAN TANAMAN
A7: 4.1.1 | B7: HSD Pengadaan dan Pengangkutan Tanaman
A8: 4.1.1.2 | B8: Analisis Produktivitas Truck Angkutan Pohon kecil di Polybag 20 L
A9: 4.1.1.3 | B9: Pengadaan dan Pengangkutan Pohon Kecil di Polybag 20 Liter | C9: pohon | D9: =ANGKUTAN!G15 -> 14797.75
A10: 4.1.1.5 | B10: Pengadaan dan Pengangkutan Pohon Kecil di Polybag 25 Liter | C10: pohon | D10: =ANGKUTAN!G31 -> 15595.25
A11: 4.1.1.7 | B11: Pengadaan dan Pengangkutan Pohon Sedang di Polybag 50 Liter | C11: pohon | D11: =ANGKUTAN!G47 -> 18546
A12: 4.1.1.9 | B12: Pengadaan dan Pengangkutan Pohon Sedang di Polybag 75 Liter | C12: pohon | D12: =ANGKUTAN!G63 -> 25437.5
A13: 4.1.1.11 | B13: Pengadaan dan Pengangkutan Pohon Besar di Polybag 100 Liter | C13: pohon | D13: =ANGKUTAN!G80 -> 83382.75
A14: 4.1.1.13 | B14: Pengadaan dan Pengangkutan Pohon Besar di Polybag 150 Liter | C14: pohon | D14: =ANGKUTAN!G97 -> 85877
A15: 4.1.1.15 | B15: Pengadaan dan Pengangkutan Pohon Besar di Polybag 200 Liter | C15: pohon | D15: =ANGKUTAN!G114 -> 114053.5
A16: 4.1.1.17 | B16: Pengadaan dan Pengangkutan Pohon Besar di Polybag 250 Liter | C16: pohon | D16: =ANGKUTAN!G131 -> 148274.5
A17: 4.1.1.19 | B17: Pengadaan dan Pengangkutan Palem Rumpun Kecil di Polybag 11 L | C17: pohon | D17: =ANGKUTAN!G147 -> 12097.25
A18: 4.1.1.21 | B18: Pengadaan dan Pengangkutan Palem Rumpun Kecil di Polybag 20 L | C18: pohon | D18: =ANGKUTAN!G163 -> 14357.75
A19: 4.1.1.23 | B19: Pengadaan dan Pengangkutan Palem Rumpun Besar di Polybag 50 L | C19: pohon | D19: =ANGKUTAN!G179 -> 18546
A20: 4.1.1.25 | B20: Pengadaan dan Pengangkutan Palem Tunggal Kecil di Polybag 11 L | C20: pohon | D20: =ANGKUTAN!G195 -> 12097.25
A21: 4.1.1.27 | B21: Pengadaan dan Pengangkutan Palem Tunggal Kecil di Polybag 20 L | C21: pohon | D21: =ANGKUTAN!G211 -> 14357.75
A22: 4.1.1.29 | B22: Pengadaan dan Pengangkutan Palem Tunggal Kecil di Polybag 25 L | C22: pohon | D22: =ANGKUTAN!G227 -> 15595.25
A23: 4.1.1.31 | B23: Pengadaan dan Pengangkutan Palem Tunggal Kecil di Polybag 50 L | C23: pohon | D23: =ANGKUTAN!G243 -> 18546
A24: 4.1.1.33 | B24: Pengadaan dan Pengangkutan Palem Tunggal Besar di Polybag 100 L | C24: pohon | D24: =ANGKUTAN!G260 -> 83382.75
A25: 4.1.1.35 | B25: Pengadaan dan Pengangkutan Palem Tunggal Besar di Polybag 150 L | C25: pohon | D25: =ANGKUTAN!G277 -> 85877
A26: 4.1.1.37 | B26: Pengadaan dan Pengangkutan Semak di Polybag 5 Liter | C26: polybag | D26: =ANGKUTAN!G293 -> 11803
A27: 4.1.1.39 | B27: Pengadaan dan Pengangkutan Semak di Polybag 11 Liter | C27: polybag | D27: =ANGKUTAN!G309 -> 12097.25
A28: 4.1.1.41 | B28: Pengadaan dan Pengangkutan Semak di Polybag 20 Liter | C28: polybag | D28: =ANGKUTAN!G325 -> 14357.75
A29: 4.1.1.25 | B29: Pengadaan dan Pengangkutan Penutup Tanah | C29: m2 | D29: =ANGKUTAN!G341 -> 12680.25
A30: 4.1.1.27 | B30: Pengadaan dan Pengangkutan Rumput | C30: m2 | D30: =ANGKUTAN!G357 -> 14371.5
A32: 4.1.2 | B32: Penanaman Pohon
A33: 4.1.2.1 | B33: Pohon Kecil, Polybag 20 L
A34: 4.1.2.1.1 | B34: Penanaman 1 Buah Pohon Kecil Bunga Mentega (Nerium Oleander) Diameter 1-2 cm, Tinggi 2-2,5 Meter, Polybag 20 L | C34: buah | D34: ='4. AHS LANDSKAP'!G25 -> 190202.1 | F34: =LEFT(B32(B34)-3) -> #REF!
A35: 4.1.2.1.2 | B35: Penanaman 1 Buah Pohon Kecil Bunga Terompet Kuning (Tecoma Stans) Diameter 1-2 cm, Tinggi 2-2,5 meter, Polybag 20L | C35: buah | D35: ='4. AHS LANDSKAP'!G51 -> 190202.1
A36: 4.1.2.1.3 | B36: Penanaman 1 Buah Pohon Kecil Bungur Sakura/Bungur Jepang (Lagerstroemia Indica) Diameter 1-2 cm, Tinggi 2-2,5 meter, Polybag 20 L | C36: buah | D36: ='4. AHS LANDSKAP'!G76 -> 190202.1
A37: 4.1.2.1.4 | B37: Penanaman 1 Buah Pohon Kecil Cassia Glauca/Hujan Emas (Senna Surattensis) Diameter 1-2 cm, Tinggi 2-2,5 meter, Polybag 20 L | C37: buah | D37: ='4. AHS LANDSKAP'!G101 -> 190202.1
A38: 4.1.2.1.5 | B38: Penanaman 1 Buah Pohon Kecil Dracaena ‘Song of India’ (Dracaena Reflexa "Song of India") Diameter 1-2 cm, Tinggi 2-2,5 meter, Polybag 20 L | C38: buah | D38: ='4. AHS LANDSKAP'!G126 -> 190202.1
A39: 4.1.2.1.6 | B39: Penanaman 1 Buah Pohon Kecil Dracaena 'Song of Jamaica' (Dracaena Reflexa "Song of Jamaica") Diameter 1-2 cm, Tinggi 2-2,5 meter, Polybag 20 L | C39: buah | D39: ='4. AHS LANDSKAP'!G151 -> 190202.1
A40: 4.1.2.1.7 | B40: Penanaman 1 Buah Pohon Kecil Jarak Batavia (Jatropha Integerrima) Diameter 1-2 cm, Tinggi 2-2,5 meter, Polybag 20 L | C40: buah | D40: ='4. AHS LANDSKAP'!G175 -> 190202.1
A41: 4.1.2.1.8 | B41: Penanaman 1 Buah Pohon Kecil Kayu Putih Kuning (Melaleuca Revolution Gold) Diameter 1-2 cm, Tinggi 2-2,5 meter, Polybag 20L | C41: buah | D41: ='4. AHS LANDSKAP'!G199 -> 190202.1
A42: 4.1.2.1.9 | B42: Penanaman 1 Buah Pohon Kecil Bugenvil/Bunga Kertas (Bougainvillea sp.) Diameter 1-2 cm, Tinggi 2-2,5 meter, Polybag 20L | C42: buah | D42: ='4. AHS LANDSKAP'!G223 -> 190202.1
...

Sheet 4. AHS LANDSKAP
A1: 4.1.2 Penanaman Pohon
A2: 4.1.2.1 Pohon Kecil, Polybag 20 L
A3: 4.1.2.1.1 Penanaman 1 Buah Pohon Kecil Bunga Mentega (Nerium Oleander) Diameter 1-2 cm, Tinggi 2-2,5 Meter, Polybag 20 L
A4: No | B4: Uraian | C4: Kode | D4: Satuan | E4: Koefisien | F4: Harga Satuan (Rp.) | G4: Jumlah Harga (Rp.)
A5: A | B5: TENAGA KERJA
A6: 1 | B6: Tukang Tanam | C6: L.02 | D6: OH | E6: 0,0143 | F6: =VLOOKUP(B6,'HSD UPAH,BAHAN,ALAT'!$C$6:F304,4,FALSE) -> 100000 | G6: =E6*F6 -> 1430
A7: 2 | B7: Kepala Tukang Tanam | C7: L.03 | D7: OH | E7: 0,0048 | F7: =VLOOKUP(B7,'HSD UPAH,BAHAN,ALAT'!$C$6:F304,4,FALSE) -> 120000 | G7: =E7*F7 -> 576
A8: 3 | B8: Mandor | C8: L.04 | D8: OH | E8: 0,0016 | F8: =VLOOKUP(B8,'HSD UPAH,BAHAN,ALAT'!$C$6:F304,4,FALSE) -> 100000 | G8: =E8*F8 -> 160
A9: Jumlah Harga Tenaga Kerja | G9: =SUM(G5:G8) -> 2166
A10: B | B10: BAHAN
A11: 1 | B11: Pohon Bunga Mentega di Polybag 20 Liter | D11: buah | E11: 1,05 | F11: =VLOOKUP(B11,'HSD UPAH,BAHAN,ALAT'!$C$6:F318,4,FALSE) -> 10000 | G11: =E11*F11 -> 10500
A12: 2 | B12: Anti Rayap pada Tanah | D12: kg | E12: 0,005 | F12: =VLOOKUP(B12,'HSD UPAH,BAHAN,ALAT'!$C$6:F319,4,FALSE) -> 10000 | G12: =E12*F12 -> 50
A13: 3 | B13: Steger | G13: =E13*F13 -> 0
A14: a | B14: bambu* dia. 3-5 cm | D14: m' | E14: 6,00 | F14: =VLOOKUP(B14,'HSD UPAH,BAHAN,ALAT'!$C$6:F321,4,FALSE) -> 10000 | G14: =E14*F14 -> 60000
A15: b | B15: tali ijuk/pengikat sejenisnya | D15: m' | E15: 10,00 | F15: =VLOOKUP(B15,'HSD UPAH,BAHAN,ALAT'!$C$6:F322,4,FALSE) -> 10000 | G15: =E15*F15 -> 100000
A16: 4 | B16: Media Tanam | G16: =E16*F16 -> 0
A17: a | B17: tanah subur : 75 % | D17: m3 | E17: 0,0146 | F17: =VLOOKUP(B17,'HSD UPAH,BAHAN,ALAT'!$C$6:F324,4,FALSE) -> 10000 | G17: =E17*F17 -> 146
A18: b | B18: pupuk organik : 20 % | D18: m3 | E18: 0,0039 | F18: =VLOOKUP(B18,'HSD UPAH,BAHAN,ALAT'!$C$6:F325,4,FALSE) -> 10000 | G18: =E18*F18 -> 39
A19: c | B19: pasir pasang : 5 % | D19: m3 | E19: 0,0010 | F19: =VLOOKUP(B19,'HSD UPAH,BAHAN,ALAT'!$C$6:F326,4,FALSE) -> 10000 | G19: =E19*F19 -> 10
A20: Jumlah Harga Bahan | G20: =SUM(G11:G19) -> 170745
A21: C | B21: PERALATAN
A22: Jumlah Harga Alat | G22: =SUM(G21) -> 0
A23: D | B23: Jumlah Harga Tenaga Kerja, Bahan dan Peralatan (A+B+C) | G23: =SUM(G5:G22)/2 -> 172911
A24: E | B24: Biaya Umum dan Keuntungan (10% - 15%) x D | F24: 0.1 | G24: =G23*F24 -> 17291.1
A25: F | B25: Harga Satuan Pekerjaan (D+E) | G25: =G23+G24 -> 190202.1
A26: *) panjang bambu 2 m' x 3 batang
A28: 4.1.2.1.2 Penanaman 1 Buah Pohon Kecil Bunga Terompet Kuning
A29: (Tecoma Stans) Diameter 1-2 cm, Tinggi 2-2,5 meter, Polybag 20L
A30: No | B30: Uraian | C30: Kode | D30: Satuan | E30: Koefisien | F30: Harga Satuan (Rp.) | G30: Jumlah Harga (Rp.)
A31: A | B31: TENAGA KERJA
A32: 1 | B32: Tukang Tanam | C32: L.02 | D32: OH | E32: 0,0143 | F32: =VLOOKUP(B32,'HSD UPAH,BAHAN,ALAT'!$C$6:F335,4,FALSE) -> 100000 | G32: =E32*F32 -> 1430
A33: 2 | B33: Kepala Tukang Tanam | C33: L.03 | D33: OH | E33: 0,0048 | F33: =VLOOKUP(B33,'HSD UPAH,BAHAN,ALAT'!$C$6:F336,4,FALSE) -> 120000 | G33: =E33*F33 -> 576
A34: 3 | B34: Mandor | C34: L.04 | D34: OH | E34: 0,0016 | F34: =VLOOKUP(B34,'HSD UPAH,BAHAN,ALAT'!$C$6:F337,4,FALSE) -> 100000 | G34: =E34*F34 -> 160
A35: Jumlah Harga Tenaga Kerja | G35: =SUM(G31:G34) -> 2166
A36: B | B36: BAHAN
A37: 1 | B37: Pohon Bunga Terompet Kuning di Polybag 20 Liter | D37: buah | E37: 1,05 | F37: =VLOOKUP(B37,'HSD UPAH,BAHAN,ALAT'!$C$6:F340,4,FALSE) -> 10000 | G37: =E37*F37 -> 10500
A38: 2 | B38: Anti Rayap pada Tanah | D38: kg | E38: 0,005 | F38: =VLOOKUP(B38,'HSD UPAH,BAHAN,ALAT'!$C$6:F341,4,FALSE) -> 10000 | G38: =E38*F38 -> 50
A39: 3 | B39: Steger | G39: =E39*F39 -> 0
A40: a | B40: bambu* dia. 3-5 cm | D40: m' | E40: 6,00 | F40: =VLOOKUP(B40,'HSD UPAH,BAHAN,ALAT'!$C$6:F343,4,FALSE) -> 10000 | G40: =E40*F40 -> 60000
A41: b | B41: tali ijuk/pengikat sejenisnya | D41: m' | E41: 10,00 | F41: =VLOOKUP(B41,'HSD UPAH,BAHAN,ALAT'!$C$6:F344,4,FALSE) -> 10000 | G41: =E41*F41 -> 100000
...

Sheet ANGKUTAN
A1: 4.1.1.3 Pengadaan dan Pengangkutan Pohon Kecil di Polybag 20 Liter
A2: No | B2: Uraian | C2: Kode | D2: Satuan | E2: Koefisien | F2: Harga Satuan (Rp.) | G2: Jumlah Harga (Rp.)
A3: A | B3: TENAGA KERJA
A4: 1 | B4: Pekerja | C4: L.01 | D4: OJ | E4: 0,0256 | F4: =VLOOKUP(B4,'HSD UPAH,BAHAN,ALAT'!$C$6:F482,4,FALSE) -> 100000 | G4: =E4*F4 -> 2560
A5: 2 | B5: Mandor | C5: L.04 | D5: OJ | E5: 0,0026 | F5: =VLOOKUP(B5,'HSD UPAH,BAHAN,ALAT'!$C$6:F483,4,FALSE) -> 100000 | G5: =E5*F5 -> 260
A6: Jumlah Harga Tenaga Kerja | G6: =SUM(G4:G5) -> 2820
A7: B | B7: BAHAN
A8: 1 | B8: Pohon Pucuk Merah di Polybag 20 Liter | D8: pohon | E8: 1,00 | F8: =VLOOKUP(B8,'HSD UPAH,BAHAN,ALAT'!$C$6:F486,4,FALSE) -> 10000 | G8: =E8*F8 -> 10000
A9: Jumlah Harga Bahan | G9: =SUM(G8) -> 10000
A10: C | B10: PERALATAN
A11: 1 | B11: Colt T-120 (D); R-Blk. 4; 12 m3 | D11: Jam | E11: 0,0253 | F11: =VLOOKUP(B11,'HSD UPAH,BAHAN,ALAT'!$C$6:F489,4,FALSE) -> 25000 | G11: =E11*F11 -> 632.5
A12: Jumlah Harga Alat | G12: =SUM(G11) -> 632.5
A13: D | B13: Jumlah Harga Tenaga Kerja, Bahan dan Peralatan (A+B+C) | G13: =SUM(G4:G12)/2 -> 13452.5
A14: E | B14: Biaya Umum dan Keuntungan (10% - 15%) x D | F14: 0.1 | G14: =G13*F14 -> 1345.25
A15: F | B15: Harga Satuan Pekerjaan (D+E) | G15: =G13+G14 -> 14797.75
A17: 4.1.1.5 Pengadaan dan Pengangkutan Pohon Kecil di Polybag 25 Liter
A18: No | B18: Uraian | C18: Kode | D18: Satuan | E18: Koefisien | F18: Harga Satuan (Rp.) | G18: Jumlah Harga (Rp.)
A19: A | B19: TENAGA KERJA
A20: 1 | B20: Pekerja | C20: L.01 | D20: OJ | E20: 0,0299 | F20: =VLOOKUP(B20,'HSD UPAH,BAHAN,ALAT'!$C$6:F498,4,FALSE) -> 100000 | G20: =E20*F20 -> 2990
A21: 2 | B21: Mandor | C21: L.04 | D21: OJ | E21: 0,0030 | F21: =VLOOKUP(B21,'HSD UPAH,BAHAN,ALAT'!$C$6:F499,4,FALSE) -> 100000 | G21: =E21*F21 -> 300
A22: Jumlah Harga Tenaga Kerja | G22: =SUM(G20:G21) -> 3290
A23: B | B23: BAHAN
A24: 1 | B24: Pohon Pucuk Merah di Polybag 25 Liter | D24: pohon | E24: 1,00 | F24: =VLOOKUP(B24,'HSD UPAH,BAHAN,ALAT'!$C$6:F502,4,FALSE) -> 10000 | G24: =E24*F24 -> 10000
A25: Jumlah Harga Bahan | G25: =SUM(G24) -> 10000
A26: C | B26: PERALATAN
A27: 1 | B27: Colt T-120 (D); R-Blk. 4; 12 m3 | D27: Jam | E27: 0,0355 | F27: =VLOOKUP(B27,'HSD UPAH,BAHAN,ALAT'!$C$6:F505,4,FALSE) -> 25000 | G27: =E27*F27 -> 887.5
A28: Jumlah Harga Alat | G28: =SUM(G27) -> 887.5
A29: D | B29: Jumlah Harga Tenaga Kerja, Bahan dan Peralatan (A+B+C) | G29: =SUM(G19:G28)/2 -> 14177.5
A30: E | B30: Biaya Umum dan Keuntungan (10% - 15%) x D | F30: 0.1 | G30: =G29*F30 -> 1417.75
A31: F | B31: Harga Satuan Pekerjaan (D+E) | G31: =G29+G30 -> 15595.25
A33: 4.1.1.7 Pengadaan dan Pengangkutan Pohon Sedang di Polybag 50 Liter
A34: No | B34: Uraian | C34: Kode | D34: Satuan | E34: Koefisien | F34: Harga Satuan (Rp.) | G34: Jumlah Harga (Rp.)
A35: A | B35: TENAGA KERJA
A36: 1 | B36: Pekerja | C36: L.01 | D36: OJ | E36: 0,0563 | F36: =VLOOKUP(B36,'HSD UPAH,BAHAN,ALAT'!$C$6:F514,4,FALSE) -> 100000 | G36: =E36*F36 -> 5630
A37: 2 | B37: Mandor | C37: L.04 | D37: OJ | E37: 0,0056 | F37: =VLOOKUP(B37,'HSD UPAH,BAHAN,ALAT'!$C$6:F515,4,FALSE) -> 100000 | G37: =E37*F37 -> 560
A38: Jumlah Harga Tenaga Kerja | G38: =SUM(G36:G37) -> 6190
A39: B | B39: BAHAN
A40: 1 | B40: Pohon Bunga Kupu-kupu di Polybag 50 Liter | D40: pohon | E40: 1,00 | F40: =VLOOKUP(B40,'HSD UPAH,BAHAN,ALAT'!$C$6:F518,4,FALSE) -> 10000 | G40: =E40*F40 -> 10000
A41: Jumlah Harga Bahan | G41: =SUM(G40) -> 10000
A42: C | B42: PERALATAN
...

Sheet HSD UPAH,BAHAN,ALAT
B1: HARGA SATUAN DASAR LANSEKAP
B2: UPAH TENAGA KERJA, BAHAN DAN PERALATAN
B4: NO. | C4: URAIAN | D4: KODE | E4: SATUAN | F4: HARGA | G4: KET.
B5: A. | C5: UPAH TENAGA KERJA
B6: 1 | C6: Kepala Tukang | E6: OH | F6: 120000
B7: 2 | C7: Tukang | E7: OH | F7: 100000
B8: 3 | C8: Tukang cat/ pelitur | E8: OH | F8: =+$F$7 -> 100000
B9: 4 | C9: Tukang Pemelihara Taman | E9: OH | F9: =+$F$7 -> 100000
B10: 5 | C10: Tukang Pemelihara Tanam | E10: OH | F10: =+$F$7 -> 100000
B11: 6 | C11: Tukang Tanam | E11: OH | F11: =+$F$7 -> 100000
B12: 7 | C12: Tukang Besi/ Besi Beton | E12: OH | F12: 100000
B13: 8 | C13: Tukang Cat | E13: OH | F13: =+$F$7 -> 100000
B14: 9 | C14: Tukang Cat/Pelitur | E14: OH | F14: =+$F$7 -> 100000
B15: 10 | C15: Tukang Ereksi | E15: OH | F15: =+$F$7 -> 100000
B16: 11 | C16: Tukang Kayu | E16: OH | F16: =+$F$7 -> 100000
B17: 12 | C17: Tukang Las | E17: OH | F17: =+$F$7 -> 100000
B18: 13 | C18: Tukang Las Konstruksi | E18: OH | F18: =+$F$7 -> 100000
B19: 14 | C19: Tukang Pipa | E19: OH | F19: =+$F$7 -> 100000
B20: 15 | C20: Tukang Listrik | E20: OH | F20: =+$F$7 -> 100000
B21: 16 | C21: Tukang Kaca | E21: OH | F21: =+$F$7 -> 100000
B22: 17 | C22: Tukang vibrator | E22: OH | F22: =+$F$7 -> 100000
B23: 18 | C23: Tukang penganyam bronjong | E23: OH | F23: 100000
B24: 19 | C24: Pekerja | E24: OH | F24: 100000
B25: 20 | C25: Mandor | E25: OH | F25: 100000
B26: 21 | C26: Kepala Tukang Tanam | E26: OH | F26: 120000
B28: B. | C28: BAHAN
B30: 1 | C30: Air | E30: liter | F30: 10000
B31: 2 | C31: Air bersih | E31: liter | F31: 10000
B32: 3 | C32: Anti Rayap pada Tanah | E32: kg | F32: 10000
B33: 4 | C33: bambu* dia. 10-12 cm | E33: m' | F33: 10000
B34: 5 | C34: bambu* dia. 3-5 cm | E34: m' | F34: 10000
B35: 6 | C35: bambu* dia. 5-8 cm | E35: m' | F35: 10000
B36: 7 | C36: bambu* dia. 8-10 cm | E36: m' | F36: 10000
B37: 8 | C37: Besi hollow 30x60 | E37: m | F37: 10000
B38: 9 | C38: Bibit Vegetasi (Biji Legume Crop Cover/LCC) | E38: kg | F38: 10000
B39: 10 | C39: Bibit Vegetasi (Biji Rumput) | E39: kg | F39: 10000
B40: 11 | C40: Cat Minyak | E40: liter | F40: 10000
B41: 12 | C41: Fungisida/insektisida | E41: kg | F41: 10000
... B287: 258 | C287: Palem Rumpun (Palem Waregu) di Polybag 11 Liter | E287: Polybag | F287: 10000
B288: 259 | F288: 10000
...
