Workbook
Name \0: #REF!
Name \A: #REF!
Name \B: [1]A!#REF!
Name \C: #REF!
Name \D: [1]A!#REF!
Name \E: [1]A!#REF!
Name \F: #REF!
Name \G: [1]A!#REF!
Name \H: #REF!
Name \H1: #REF!
Name \H2: #REF!
Name \H4: #REF!
Name \H5: #REF!
Name \H6: #REF!
Name \H7: #REF!
Name \J: #REF!
Name \K: #REF!
Name \L: [1]A!#REF!
Name \M: [1]A!#REF!
Name \N: #REF!
Name \O: #REF!
Name \P: #REF!
Name \R: [1]A!#REF!
Name \S: #REF!
Name \T: [1]A!#REF!
Name \U: [1]A!#REF!
Name \V: [1]A!#REF!
Name \W: #REF!
Name \X: [1]A!#REF!
Name \Y: #REF!
Name \Z: [1]A!#REF!
Name _: #REF!
Name __?___RIGHT__?_: #REF!
Name ___: [2]ANALIS!#REF!
Name ____________________________DIV11: #REF!
Name ___________________________MMM19: '[3]4-Basic Price'!$F$71
Name __________________________DIV11: #REF!
Name __________________________EEE02: #REF!
Name __________________________EEE05: #REF!
Name __________________________EEE06: #REF!
Name __________________________EEE07: #REF!
Name __________________________EEE08: #REF!
Name __________________________EEE09: #REF!
Name __________________________EEE10: #REF!
Name __________________________EEE11: #REF!
Name __________________________EEE13: #REF!
Name __________________________EEE15: #REF!
Name __________________________EEE16: #REF!
Name __________________________EEE17: #REF!
Name __________________________EEE22: #REF!
Name __________________________EEE23: #REF!
Name __________________________EEE27: #REF!
Name __________________________EEE29: #REF!
Name __________________________HAL2: #REF!
Name __________________________HAL5: #REF!
Name __________________________HAL6: #REF!
Name __________________________HAL7: #REF!
Name __________________________HAL8: #REF!
Name __________________________MMM19: '[4]4-Basic Price'!$F$69
Name __________________________MMM38: '[4]4-Basic Price'!#REF!

Sheet INFORMASI
A1: AHS PEKERJAAN ME & PLUMBING
A2: DIBUAT BERDASARKAN SURAT EDARAN BINA KONSTRUKSI NO. 182 TAHUN 2025
A5: ANALISA HARGA SATUAN INI
A6: TERDIRI DARI HSP (HARGA SATUAN PEKERJAAN), AHS (ANALISA HARGA SATUAN), HSD (HARGA SATUAN DASAR) UPAH BAHAN ALAT
A8: Untuk pembuatan RAB harap diperhatikan penjumlahan dalam analisa karena bisa berubah setiap program excel sehingga mengakibatkan ketidak validan perhitungan
B11: BACA DULU :
B12: 1. Program ini terdiri dari HSP (Harga Satuan Pekerjaan), AHS (Analisa harga satuan), HSD (Harga Satuan Dasar) Upah dan Bahan
B13: 2. Cukup merubah harga HSD maka AHS dan HSP akan langsung berubah menyesuaikan
B14: 3. AHS ini dibuat berdasarkan SE Bina Konstruksi No. 182 tahun 2025, sebagai update dari SE BK No. 30 Tahun 2025
B15: 4. Untuk membuat RAB, cukup cari pekerjaan yang sesuai di HSP, lalu dari HSP cek AHS, dari AHS kemudian rubah harga bahan di HSD, otomatis AHS dan HSP akan berubah menyesuaikan, harga pada HSP bisa digunakan untuk RAB
B16: 5. Harga default untuk Bahan dan alat adalah Rp.10.000 yang bisa diubah sesuai harga setempat

Sheet HSP ME
A1: 6 PEKERJAAN ME
A2: HARGA SATUAN PEKERJAAN
A4: No. Mata Pembayaran | B4: Uraian | C4: Satuan | D4: Harga Satuan (Rp)
A5: 5.1 | B5: PEKERJAAN SISTEM DISTRIBUSI JARINGAN LISTRIK
A6: 5.1.1 | B6: Pemasangan kabel arus kuat (kabel, kabel tray/ladder)
A7: 5.1.1.1 | B7: Kabel NYY
A8: 5.1.1.1.1 | B8: Pemasangan 1 m’ Kabel NYY 1 x 4 mm² | C8: m' | D8: ='5. AHS ME'!G20 -> 22770
A9: 5.1.1.1.2 | B9: Pemasangan 1 m’ Kabel NYY 1 x 6 mm² | C9: m' | D9: ='5. AHS ME'!G37 -> 22770
A10: 5.1.1.1.3 | B10: Pemasangan 1 m’ Kabel NYY 1 x 10 mm² | C10: m' | D10: ='5. AHS ME'!G54 -> 22770
A11: 5.1.1.1.4 | B11: Pemasangan 1 m’ Kabel NYY 1 x 16 mm² | C11: m' | D11: ='5. AHS ME'!G71 -> 22770
A12: 5.1.1.1.5 | B12: Pemasangan 1 m’ Kabel NYY 1 x 25 mm² | C12: m' | D12: ='5. AHS ME'!G88 -> 25025
A13: 5.1.1.1.6 | B13: Pemasangan 1 m’ Kabel NYY 1 x 35 mm² | C13: m' | D13: ='5. AHS ME'!G105 -> 27940
A14: 5.1.1.1.7 | B14: Pemasangan 1 m’ Kabel NYY 1 x 50 mm² | C14: m' | D14: ='5. AHS ME'!G122 -> 27940
A15: 5.1.1.1.8 | B15: Pemasangan 1 m’ Kabel NYY 1 x 70 mm² | C15: m' | D15: ='5. AHS ME'!G139 -> 37895
A16: 5.1.1.1.9 | B16: Pemasangan 1 m’ Kabel NYY 1 x 95 mm² | C16: m' | D16: ='5. AHS ME'!G156 -> 37895
A17: 5.1.1.1.10 | B17: Pemasangan 1 m’ Kabel NYY 1 x 120 mm² | C17: m' | D17: ='5. AHS ME'!G173 -> 37895
A18: 5.1.1.1.11 | B18: Pemasangan 1 m’ Kabel NYY 1 x 150 mm² | C18: m' | D18: ='5. AHS ME'!G190 -> 37895
A19: 5.1.1.1.12 | B19: Pemasangan 1 m’ Kabel NYY 1 x 185 mm² | C19: m' | D19: ='5. AHS ME'!G207 -> 42955
A20: 5.1.1.1.13 | B20: Pemasangan 1 m’ Kabel NYY 1 x 240 mm² | C20: m' | D20: ='5. AHS ME'!G224 -> 42955
A21: 5.1.1.1.14 | B21: Pemasangan 1 m’ Kabel NYY 1 x 300 mm² | C21: m' | D21: ='5. AHS ME'!G241 -> 48125
A22: 5.1.1.1.15 | B22: Pemasangan 1 m’ Kabel NYY 1 x 400 mm² | C22: m' | D22: ='5. AHS ME'!G258 -> 53075
A23: 5.1.1.1.16 | B23: Pemasangan 1 m’ Kabel NYY 1 x 500 mm² | C23: m' | D23: ='5. AHS ME'!G275 -> 63415
A24: 5.1.1.1.17 | B24: Pemasangan 1 m’ Kabel NYY 1 x 630 mm² | C24: m' | D24: ='5. AHS ME'!G292 -> 73535
A25: 5.1.1.1.18 | B25: Pemasangan 1 m’ Kabel NYY 2 x 1,5 mm² | C25: m' | D25: ='5. AHS ME'!G309 -> 22770
A26: 5.1.1.1.19 | B26: Pemasangan 1 m’ Kabel NYY 2 x 2,5 mm² | C26: m' | D26: ='5. AHS ME'!G326 -> 22770
A27: 5.1.1.1.20 | B27: Pemasangan 1 m’ Kabel NYY 2 x 4 mm² | C27: m' | D27: ='5. AHS ME'!G343 -> 22770
A28: 5.1.1.1.21 | B28: Pemasangan 1 m’ Kabel NYY 2 x 6 mm² | C28: m' | D28: ='5. AHS ME'!G360 -> 22770
A29: 5.1.1.1.22 | B29: Pemasangan 1 m’ Kabel NYY 2 x 10 mm² | C29: m' | D29: ='5. AHS ME'!G377 -> 22770
A30: 5.1.1.1.23 | B30: Pemasangan 1 m’ Kabel NYY 2 x 16 mm² | C30: m' | D30: ='5. AHS ME'!G394 -> 22770
A31: 5.1.1.1.24 | B31: Pemasangan 1 m’ Kabel NYY 3 x 1,5 mm² | C31: m' | D31: ='5. AHS ME'!G411 -> 22770
A32: 5.1.1.1.25 | B32: Pemasangan 1 m’ Kabel NYY 3 x 2,5 mm² | C32: m' | D32: ='5. AHS ME'!G428 -> 22770
A33: 5.1.1.1.26 | B33: Pemasangan 1 m’ Kabel NYY 3 x 4 mm² | C33: m' | D33: ='5. AHS ME'!G445 -> 25025
A34: 5.1.1.1.27 | B34: Pemasangan 1 m’ Kabel NYY 3 x 6 mm² | C34: m' | D34: ='5. AHS ME'!G462 -> 25025
A35: 5.1.1.1.28 | B35: Pemasangan 1 m’ Kabel NYY 3 x 10 mm² | C35: m' | D35: ='5. AHS ME'!G479 -> 27940
A36: 5.1.1.1.29 | B36: Pemasangan 1 m’ Kabel NYY 3 x 16 mm² | C36: m' | D36: ='5. AHS ME'!G496 -> 27940
A37: 5.1.1.1.30 | B37: Pemasangan 1 m’ Kabel NYY 3 x 25 mm² | C37: m' | D37: ='5. AHS ME'!G513 -> 27940
A38: 5.1.1.1.31 | B38: Pemasangan 1 m’ Kabel NYY 3 x 35 mm² | C38: m' | D38: ='5. AHS ME'!G530 -> 30855
A39: 5.1.1.1.32 | B39: Pemasangan 1 m’ Kabel NYY 3 x 50 mm² | C39: m' | D39: ='5. AHS ME'!G547 -> 33110
A40: 5.1.1.1.33 | B40: Pemasangan 1 m’ Kabel NYY 4 x 1,5 mm² | C40: m' | D40: ='5. AHS ME'!G564 -> 22770
A41: 5.1.1.1.34 | B41: Pemasangan 1 m’ Kabel NYY 4 x 2,5 mm² | C41: m' | D41: ='5. AHS ME'!G581 -> 22770
...

Sheet HSP PLUMBING
A1: 6 PEKERJAAN PLAMBING
A2: HARGA SATUAN PEKERJAAN
A4: No. Mata Pembayaran | B4: Uraian | C4: Satuan | D4: Harga Satuan (Rp)
A5: 6.1 | B5: SISTEM AIR MINUM
A6: 6.1.1 | B6: Roof water tank
A7: 6.1.1.1 | B7: Pemasangan 1 Unit Roof Tank Fiberglass Kap. 2 m3 | C7: unit | D7: ='6. AHS PLUMBING'!G19 -> 188760
A8: 6.1.1.2 | B8: Pemasangan 1 Unit Roof Tank Fiberglass Kap. 4 m3 | C8: unit | D8: ='6. AHS PLUMBING'!G36 -> 286055
A9: 6.1.1.3 | B9: Pemasangan 1 Unit Roof Tank Fiberglass Kap. 12 m3 | C9: unit | D9: ='6. AHS PLUMBING'!G53 -> 339515
A10: 6.1.1.4 | B10: Pemasangan 1 Unit Roof Tank Stainless Kap. 2 m3 | C10: unit | D10: ='6. AHS PLUMBING'!G70 -> 189530
A11: 6.1.1.5 | B11: Pemasangan 1 Unit Roof Tank Stainless Kap. 4 m3 | C11: unit | D11: ='6. AHS PLUMBING'!G87 -> 286605
A12: 6.1.1.6 | B12: Pemasangan 1 Unit Roof Tank Stainless Kap. 12 m3 | C12: unit | D12: ='6. AHS PLUMBING'!G104 -> 339845
A13: 6.1.1.7 | B13: Pemasangan 1 buah Tangki Toren Kap. 0,7 m3 | C13: buah | D13: ='6. AHS PLUMBING'!G121 -> 65670
A14: 6.1.1.8 | B14: Pemasangan 1 buah Tangki Toren Kap. 1,5 m3 | C14: buah | D14: ='6. AHS PLUMBING'!G138 -> 188430
A15: 6.1.1.9 | B15: Pemasangan 1 buah Tangki Toren Kap. 2,5 m3 | C15: buah | D15: ='6. AHS PLUMBING'!G155 -> 188430
A16: 6.1.1.10 | B16: Pemasangan 1 buah Tangki Toren Kap. 3 m3 | C16: buah | D16: ='6. AHS PLUMBING'!G172 -> 285505
A17: 6.1.1.11 | B17: Pemasangan 1 buah Tangki Toren Kap. 4 m3 | C17: buah | D17: ='6. AHS PLUMBING'!G189 -> 285065
A18: 6.1.1.12 | B18: Pemasangan 1 buah Tangki Toren Kap. 5 m3 | C18: buah | D18: ='6. AHS PLUMBING'!G206 -> 285065
A19: 6.1.1.13 | B19: Pemasangan 1 buah Tangki Toren Kap. 5,5 m3 | C19: buah | D19: ='6. AHS PLUMBING'!G223 -> 285065
A20: 6.1.1.14 | B20: Pemasangan 1 buah Tangki Toren Kap. 6 m3 | C20: buah | D20: ='6. AHS PLUMBING'!G240 -> 334125
A21: 6.1.1.15 | B21: Pemasangan 1 buah Tangki Panel FRP Kap. 12 m3 | C21: buah | D21: ='6. AHS PLUMBING'!G257 -> 339295
A22: 6.1.1.16 | B22: Pemasangan 1 buah Tangki Panel Stainless Steel kap. 12 m3 | C22: buah | D22: ='6. AHS PLUMBING'!G274 -> 339295
A23: 6.1.1.17 | B23: Pemasangan 1 buah Tangki Panel GRP kap 12 m3 | C23: buah | D23: ='6. AHS PLUMBING'!G291 -> 339295
A24: 6.1.1.18 | B24: Pemasangan 1 buah Tangki Toren Kap. 0,5 m3 | C24: buah | D24: ='6. AHS PLUMBING'!G308 -> 65670
A25: 6.1.1.19 | B25: Pemasangan 1 buah Tangki Panel GRP Kap. 16 m3 (Baru) | C25: buah | D25: ='6. AHS PLUMBING'!G325 -> 341165
A26: 6.1.1.20 | B26: Pemasangan 1 buah Tangki Toren Kap. 2,2 m3 (Baru) | C26: buah | D26: ='6. AHS PLUMBING'!G342 -> 188870
A28: 6.1.2 | B28: Pompa transfer dan booster
A29: 6.1.2.1 | B29: Pemasangan 1 Unit Pompa Transfer 150 lpm; Centrifugal End Suction | C29: unit | D29: ='6. AHS PLUMBING'!G360 -> 320540
A30: 6.1.2.2 | B30: Pemasangan 1 Unit Pompa Booster 450 lpm; Centrifugal End Suction | C30: unit | D30: ='6. AHS PLUMBING'!G377 -> 188155
A31: 6.1.2.3 | B31: Pemasangan 1 Unit Pompa Booster 150 lpm; Vertical In Line – Packaged | C31: unit | D31: ='6. AHS PLUMBING'!G394 -> 188155
A32: 6.1.2.4 | B32: Pemasangan 1 Unit Pompa Jet 27 lpm | C32: unit | D32: ='6. AHS PLUMBING'!G411 -> 335555
A33: 6.1.2.5 | B33: Pemasangan 1 Unit Pompa Jet 34 lpm | C33: unit | D33: ='6. AHS PLUMBING'!G428 -> 335555
A34: 6.1.2.6 | B34: Pemasangan 1 Unit Pompa Jet 100 lpm | C34: unit | D34: ='6. AHS PLUMBING'!G445 -> 335555
A35: 6.1.2.7 | B35: Pemasangan 1 Unit Pompa Lift 80 lpm | C35: unit | D35: ='6. AHS PLUMBING'!G462 -> 276540
A36: 6.1.2.8 | B36: Pemasangan 1 Unit Pompa Lift 250 lpm | C36: unit | D36: ='6. AHS PLUMBING'!G479 -> 320980
A37: 6.1.2.9 | B37: Pemasangan 1 Unit Pompa Jet 30 lpm | C37: unit | D37: ='6. AHS PLUMBING'!G496 -> 335555
A38: 6.1.2.10 | B38: Pemasangan 1 Unit Pompa Transfer 500 lpm; Centrifugal End Suction (Baru) | C38: unit | D38: ='6. AHS PLUMBING'!G513 -> 320815
A39: 6.1.2.11 | B39: Pemasangan 1 Unit Pompa Transfer 50 lpm; Centrifugal End Suction (Baru) | C39: unit | D39: ='6. AHS PLUMBING'!G530 -> 259160
A41: 6.1.3 | B41: Filter
A42: 6.1.3.1 | B42: Pemasangan 1 Unit Sand Filter Kap. 0,1 m3/hari | C42: unit | D42: ='6. AHS PLUMBING'!G548 -> 479435
A43: 6.1.3.2 | B43: Pemasangan 1 Unit Sand Filter Kap. 14 m3/hari | C43: unit | D43: ='6. AHS PLUMBING'!G565 -> 2397285
...

Sheet 5. AHS ME
A1: 5 AHS PEKERJAAN MEKANIKAL DAN ELEKTRIKAL
A2: 5.1 | B2: PEKERJAAN SISTEM DISTRIBUSI JARINGAN LISTRIK
A3: 5.1.1 | B3: Pemasangan kabel arus kuat (kabel, kabel tray/ladder)
A4: 5.1.1.1 | B4: Kabel NYY
A5: 5.1.1.1.1 Pemasangan 1 m’ Kabel NYY 1 x 4 mm²
A6: No | B6: Uraian | C6: Kode | D6: Satuan | E6: Koefisien | F6: Harga Satuan (Rp) | G6: Jumlah Harga (Rp)
A7: A | B7: Tenaga Kerja
B8: Pekerja | C8: L.01 | D8: OH | E8: 0,024 | F8: =VLOOKUP(B8,'HSD ME&PLUMBING'!$B$6:E1670,4,FALSE) -> 100000 | G8: =F8*E8 -> 2400
B9: Tukang Listrik / Elektronik | C9: L.02 | D9: OH | E9: 0,040 | F9: =VLOOKUP(B9,'HSD ME&PLUMBING'!$B$6:E1671,4,FALSE) -> 150000 | G9: =F9*E9 -> 6000
B10: Kepala Tukang | C10: L.03 | D10: OH | E10: 0,004 | F10: =VLOOKUP(B10,'HSD ME&PLUMBING'!$B$6:E1672,4,FALSE) -> 150000 | G10: =F10*E10 -> 600
B11: Mandor | C11: L.04 | D11: OH | E11: 0,001 | F11: =VLOOKUP(B11,'HSD ME&PLUMBING'!$B$6:E1673,4,FALSE) -> 200000 | G11: =F11*E11 -> 200
A12: Jumlah Harga Tenaga Kerja | G12: =SUM(G8:G11) -> 9200
A13: B | B13: Bahan
B14: NYY 1 x 4 mm² dan aksesoris | D14: m' | E14: 1,15 | F14: =VLOOKUP(B14,'HSD ME&PLUMBING'!$B$6:E1676,4,FALSE) -> 10000 | G14: =F14*E14 -> 11500
A15: Jumlah Harga Bahan | G15: =SUM(G14) -> 11500
A16: C | B16: Peralatan
A17: Jumlah Harga Alat | G17: =SUM(G16) -> 0
A18: D | B18: Jumlah Harga Tenaga Kerja, Bahan dan Peralatan (A+B+C) | G18: =G12+G15+G17 -> 20700
A19: E | B19: Biaya Umum dan Keuntungan (10% - 15%) x D | F19: 0.1 | G19: =G18*10% -> 2070
A20: F | B20: Harga Satuan Pekerjaan (D+E) | G20: =G18+G19 -> 22770
A22: 5.1.1.1.2 Pemasangan 1 m’ Kabel NYY 1 x 6 mm²
A23: No | B23: Uraian | C23: Kode | D23: Satuan | E23: Koefisien | F23: Harga Satuan (Rp) | G23: Jumlah Harga (Rp)
A24: A | B24: Tenaga Kerja
B25: Pekerja | C25: L.01 | D25: OH | E25: 0,024 | F25: =VLOOKUP(B25,'HSD ME&PLUMBING'!$B$6:E1687,4,FALSE) -> 100000 | G25: =F25*E25 -> 2400
B26: Tukang Listrik / Elektronik | C26: L.02 | D26: OH | E26: 0,040 | F26: =VLOOKUP(B26,'HSD ME&PLUMBING'!$B$6:E1688,4,FALSE) -> 150000 | G26: =F26*E26 -> 6000
B27: Kepala Tukang | C27: L.03 | D27: OH | E27: 0,004 | F27: =VLOOKUP(B27,'HSD ME&PLUMBING'!$B$6:E1689,4,FALSE) -> 150000 | G27: =F27*E27 -> 600
B28: Mandor | C28: L.04 | D28: OH | E28: 0,001 | F28: =VLOOKUP(B28,'HSD ME&PLUMBING'!$B$6:E1690,4,FALSE) -> 200000 | G28: =F28*E28 -> 200
A29: Jumlah Harga Tenaga Kerja | G29: =SUM(G25:G28) -> 9200
A30: B | B30: Bahan
B31: NYY 1 x 6 mm² dan aksesoris | D31: m' | E31: 1,15 | F31: =VLOOKUP(B31,'HSD ME&PLUMBING'!$B$6:E1693,4,FALSE) -> 10000 | G31: =F31*E31 -> 11500
A32: Jumlah Harga Bahan | G32: =SUM(G31) -> 11500
A33: C | B33: Peralatan
A34: Jumlah Harga Alat | G34: =SUM(G33) -> 0
A35: D | B35: Jumlah Harga Tenaga Kerja, Bahan dan Peralatan (A+B+C) | G35: =G29+G32+G34 -> 20700
A36: E | B36: Biaya Umum dan Keuntungan (10% - 15%) x D | F36: 0.1 | G36: =G35*10% -> 2070
A37: F | B37: Harga Satuan Pekerjaan (D+E) | G37: =G35+G36 -> 22770
A39: 5.1.1.1.3 Pemasangan 1 m’ Kabel NYY 1 x 10 mm²
A40: No | B40: Uraian | C40: Kode | D40: Satuan | E40: Koefisien | F40: Harga Satuan (Rp) | G40: Jumlah Harga (Rp)
A41: A | B41: Tenaga Kerja
B42: Pekerja | C42: L.01 | D42: OH | E42: 0,024 | F42: =VLOOKUP(B42,'HSD ME&PLUMBING'!$B$6:E1704,4,FALSE) -> 100000 | G42: =F42*E42 -> 2400
...

Sheet 6. AHS PLUMBING
A1: 6 PEKERJAAN PLAMBING
A2: 6.1 SISTEM AIR MINUM
A3: 6.1.1 Roof water tank
A4: 6.1.1.1 Pemasangan 1 Unit Roof Tank Fiberglass Kap. 2 m3
A5: No | B5: Uraian | C5: Kode | D5: Satuan | E5: Koefisien | F5: Harga Satuan (Rp) | G5: Jumlah Harga (Rp)
A6: A | B6: Tenaga Kerja
B7: Pekerja | C7: L.01 | D7: OH | E7: 0,417 | F7: =VLOOKUP(B7,'HSD ME&PLUMBING'!$B$6:E1669,4,FALSE) -> 100000 | G7: =F7*E7 -> 41700
B8: Tukang | C8: L.02 | D8: OH | E8: 0,696 | F8: =VLOOKUP(B8,'HSD ME&PLUMBING'!$B$6:E1670,4,FALSE) -> 150000 | G8: =F8*E8 -> 104400
B9: Kepala Tukang | C9: L.03 | D9: OH | E9: 0,070 | F9: =VLOOKUP(B9,'HSD ME&PLUMBING'!$B$6:E1671,4,FALSE) -> 150000 | G9: =F9*E9 -> 10500
B10: Mandor | C10: L.04 | D10: OH | E10: 0,021 | F10: =VLOOKUP(B10,'HSD ME&PLUMBING'!$B$6:E1672,4,FALSE) -> 200000 | G10: =F10*E10 -> 4200
A11: Jumlah Harga Tenaga Kerja | G11: =SUM(G7:G10) -> 160800
A12: B | B12: Bahan
B13: Roof Tank Fiberglass Kapasitas 2 m3 + Material Bantu / Aksesoris | D13: Unit | E13: 1,080 | F13: =VLOOKUP(B13,'HSD ME&PLUMBING'!$B$6:E1675,4,FALSE) -> 10000 | G13: =F13*E13 -> 10800
A14: Jumlah Harga Bahan | G14: =SUM(G13) -> 10800
A15: C | B15: Peralatan
A16: Jumlah Harga Alat | G16: =SUM(G15) -> 0
A17: D | B17: Jumlah Harga Tenaga Kerja, Bahan dan Peralatan (A+B+C) | G17: =SUM(G7:G16)/2 -> 171600
A18: E | B18: Biaya Umum dan Keuntungan (10% - 15%) x D | F18: 0.1 | G18: =G17*F18 -> 17160
A19: F | B19: Harga Satuan Pekerjaan (D+E) | G19: =G17+G18 -> 188760
A21: 6.1.1.2 Pemasangan 1 Unit Roof Tank Fiberglass Kap. 4 m3
A22: No | B22: Uraian | C22: Kode | D22: Satuan | E22: Koefisien | F22: Harga Satuan (Rp) | G22: Jumlah Harga (Rp)
A23: A | B23: Tenaga Kerja
B24: Pekerja | C24: L.01 | D24: OH | E24: 0,646 | F24: =VLOOKUP(B24,'HSD ME&PLUMBING'!$B$6:E1686,4,FALSE) -> 100000 | G24: =F24*E24 -> 64600
B25: Tukang | C25: L.02 | D25: OH | E25: 1,079 | F25: =VLOOKUP(B25,'HSD ME&PLUMBING'!$B$6:E1687,4,FALSE) -> 150000 | G25: =F25*E25 -> 161850
B26: Kepala Tukang | C26: L.03 | D26: OH | E26: 0,108 | F26: =VLOOKUP(B26,'HSD ME&PLUMBING'!$B$6:E1688,4,FALSE) -> 150000 | G26: =F26*E26 -> 16200
B27: Mandor | C27: L.04 | D27: OH | E27: 0,032 | F27: =VLOOKUP(B27,'HSD ME&PLUMBING'!$B$6:E1689,4,FALSE) -> 200000 | G27: =F27*E27 -> 6400
A28: Jumlah Harga Tenaga Kerja | G28: =SUM(G24:G27) -> 249050
A29: B | B29: Bahan
B30: Roof Tank Fiberglass Kapasitas 4 m3 + Material Bantu / Aksesoris | D30: Unit | E30: 1,100 | F30: =VLOOKUP(B30,'HSD ME&PLUMBING'!$B$6:E1692,4,FALSE) -> 10000 | G30: =F30*E30 -> 11000
A31: Jumlah Harga Bahan | G31: =SUM(G30) -> 11000
A32: C | B32: Peralatan
A33: Jumlah Harga Alat | G33: =SUM(G32) -> 0
A34: D | B34: Jumlah Harga Tenaga Kerja, Bahan dan Peralatan (A+B+C) | G34: =SUM(G24:G33)/2 -> 260050
A35: E | B35: Biaya Umum dan Keuntungan (10% - 15%) x D | F35: 0.1 | G35: =G34*F35 -> 26005
A36: F | B36: Harga Satuan Pekerjaan (D+E) | G36: =G34+G35 -> 286055
A38: 6.1.1.3 Pemasangan 1 Unit Roof Tank Fiberglass Kap. 12 m3
A39: No | B39: Uraian | C39: Kode | D39: Satuan | E39: Koefisien | F39: Harga Satuan (Rp) | G39: Jumlah Harga (Rp)
A40: A | B40: Tenaga Kerja
B41: Pekerja | C41: L.01 | D41: OH | E41: 0,771 | F41: =VLOOKUP(B41,'HSD ME&PLUMBING'!$B$6:E1703,4,FALSE) -> 100000 | G41: =F41*E41 -> 77100
B42: Tukang | C42: L.02 | D42: OH | E42: 1,288 | F42: =VLOOKUP(B42,'HSD ME&PLUMBING'!$B$6:E1704,4,FALSE) -> 150000 | G42: =F42*E42 -> 193200
...

Sheet HSD ME&PLUMBING
A1: HARGA SATUAN DASAR ME & PLAMBING
A2: UPAH TENAGA KERJA, BAHAN DAN PERALATAN
A4: NO. | B4: URAIAN | C4: KODE | D4: SATUAN | E4: HARGA | F4: KET.
A5: A. | B5: TENAGA KERJA
A6: 1 | B6: Kepala Tukang | D6: OH | E6: ='[418]HSD PSPN,STR,ARS'!F6 -> 150000
A7: 2 | B7: Tukang | D7: OH | E7: ='[418]HSD PSPN,STR,ARS'!F7 -> 150000
A8: 3 | B8: Tukang Alumunium | D8: OH | E8: =E7 -> 150000
A9: 4 | B9: Tukang batu/tembok | D9: OH | E9: =E8 -> 150000
A10: 5 | B10: Tukang Besi | D10: OH | E10: =E9 -> 150000
A11: 6 | B11: Tukang Cat | D11: OH | E11: =E10 -> 150000
A12: 7 | B12: Tukang Kayu | D12: OH | E12: =E11 -> 150000
A13: 8 | B13: Tukang Las Konstruksi | D13: OH | E13: =E12 -> 150000
A14: 9 | B14: Tukang Pipa | D14: OH | E14: =E13 -> 150000
A15: 10 | B15: Tukang Listrik / Elektronik | D15: OH | E15: =E14 -> 150000
A16: 11 | B16: Pekerja | D16: OH | E16: ='[418]HSD PSPN,STR,ARS'!F24 -> 100000
A17: 12 | B17: Mandor | D17: OH | E17: ='[418]HSD PSPN,STR,ARS'!F25 -> 200000
A18: 13 | B18: Operator Alat Berat | D18: OH | E18: ='[418]HSD PSPN,STR,ARS'!F26 -> 200000
A19: 14 | B19: Operator Alat Pipa | D19: OH | E19: ='[418]HSD PSPN,STR,ARS'!F27 -> 200000
A20: 15 | B20: Operator Crane | D20: OH | E20: ='[418]HSD PSPN,STR,ARS'!F28 -> 200000
A21: 16 | B21: Pembantu Operator Crane | D21: OH | E21: ='[418]HSD PSPN,STR,ARS'!F29 -> 150000
A22: 17 | B22: Juru ukur | D22: OH | E22: ='[418]HSD PSPN,STR,ARS'!F30 -> 200000
A23: 18 | B23: Pembantu juru ukur | D23: OH | E23: ='[418]HSD PSPN,STR,ARS'!F31 -> 150000
A24: 19 | B24: Tenaga Terampil Operator | D24: OH | E24: ='[418]HSD PSPN,STR,ARS'!F32 -> 200000
A25: 20 | B25: Tenaga Ahli Muda | D25: OH | E25: ='[418]HSD PSPN,STR,ARS'!F33 -> 250000
A27: B. | B27: BAHAN
A28: MEKANIKAL ELEKTRIKAL
B31: KABEL
A32: 1 | B32: NYY 1 x 4 mm² dan aksesoris | D32: m' | E32: 10000
A33: 2 | B33: NYY 1 x 6 mm² dan aksesoris | D33: m' | E33: 10000
A34: 3 | B34: NYY 1 x 10 mm² dan aksesoris | D34: m' | E34: 10000
A35: 4 | B35: NYY 1 x 16 mm² dan aksesoris | D35: m' | E35: 10000
A36: 5 | B36: NYY 1 x 25 mm² dan aksesoris | D36: m' | E36: 10000
A37: 6 | B37: NYY 1 x 35 mm² dan aksesoris | D37: m' | E37: 10000
A38: 7 | B38: NYY 1 x 50 mm² dan aksesoris | D38: m' | E38: 10000
A39: 8 | B39: NYY 1 x 70 mm² dan aksesoris | D39: m' | E39: 10000
A40: 9 | B40: NYY 1 x 95 mm² dan aksesoris | D40: m' | E40: 10000
A41: 10 | B41: NYY 1 x 120 mm² dan aksesoris | D41: m' | E41: 10000
A42: 11 | B42: NYY 1 x 150 mm² dan aksesoris | D42: m' | E42: 10000
A43: 12 | B43: NYY 1 x 185 mm² dan aksesoris | D43: m' | E43: 10000
... A157: 126 | B157: BCC 4 mm2 (0,04 kg/m) dan aksesoris | D157: m' | E157: 10000
...
