Workbook

Sheet INFORMASI
A1: AHS PEKERJAAN SISTIM STRUKTUR RISHA
A2: DIBUAT BERDASARKAN SURAT EDARAN BINA KONSTRUKSI NO. 182 TAHUN 2025
A5: ANALISA HARGA SATUAN INI
A6: TERDIRI DARI HSP (HARGA SATUAN PEKERJAAN), AHS (ANALISA HARGA SATUAN), HSD (HARGA SATUAN DASAR) UPAH BAHAN ALAT
A8: Untuk pembuatan RAB harap diperhatikan penjumlahan dalam analisa karena bisa berubah setiap program excel sehingga mengakibatkan ketidak validan perhitungan
B11: BACA DULU :
B12: 1. Program ini terdiri dari HSP (Harga Satuan Pekerjaan), AHS (Analisa harga satuan), HSD (Harga Satuan Dasar) Upah dan Bahan
B13: 2. Cukup merubah harga HSD maka AHS dan HSP akan langsung berubah menyesuaikan
B14: 3. AHS ini dibuat berdasarkan SE Bina Konstruksi No. 182 tahun 2025, sebagai update dari SE BK No. 30 Tahun 2025
B15: 4. Untuk membuat RAB, cukup cari pekerjaan yang sesuai di HSP, lalu dari HSP cek AHS, dari AHS kemudian rubah harga bahan di HSD, otomatis AHS dan HSP akan berubah menyesuaikan, harga pada HSP bisa digunakan untuk RAB
B16: 5. Harga default untuk Bahan dan alat adalah Rp.10.000 yang bisa diubah sesuai harga setempat

Sheet HSP
A1: 5 PEKERJAAN SISTEM STRUKTUR RISHA
A2: HARGA SATUAN PEKERJAAN
A4: NO | B4: KODE ANALISA & PEKERJAAN | C4: SATUAN | D4: HARGA SAT
A6: 1 | B6: 10 SISTEM STRUKTUR RISHA
A7: 2 | B7: 10.1 Pekerjaan Produksi Panel RISHA
A8: 3 | B8: 10.1.1 Pembuatan 1 buah Cetakan Panel P1 RISHA (Asumsi 400 kali pakai) | C8: buah | D8: =AHS!G20 -> 621879
A9: 4 | B9: 10.1.2 Pembuatan 1 buah Cetakan Panel P2 RISHA (Asumsi 400 kali pakai) | C9: buah | D9: =AHS!G39 -> 547991
A10: 5 | B10: 10.1.3 Pembuatan 1 buah Cetakan Panel P3 RISHA (Asumsi 400 kali pakai) | C10: buah | D10: =AHS!G58 -> 300968
A11: 6 | B11: 10.1.4 Pemasangan dan Membuka Cetakan 1 buah Komponen P1 RISHA | C11: buah | D11: =AHS!G74 -> 1892
A12: 7 | B12: 10.1.5 Pemasangan dan Membuka Cetakan 1 buah Komponen P2 RISHA | C12: buah | D12: =AHS!G90 -> 1628
A13: 8 | B13: 10.1.6 Pemasangan dan Membuka Cetakan 1 buah Komponen P3 RISHA | C13: buah | D13: =AHS!G106 -> 1430
A14: 9 | B14: 10.1.7 Produksi 1 buah Panel P1 | C14: buah | D14: =AHS!G124 -> 0
A15: 10 | B15: 10.1.8 Produksi 1 buah Panel P2 | C15: buah | D15: =AHS!G142 -> 0
A16: 11 | B16: 10.1.9 Produksi 1 buah Panel P3 | C16: buah | D16: =AHS!G159 -> 0
A18: 10 | B18: 10.2 Pekerjaan Pengepakkan dan Pengiriman Panel lengkap dengan Aksesories RISHA
A19: 11 | B19: 10.2.1 Pengepakan 1 set Panel dan Aksesories RISHA T-36 | C19: set | D19: =AHS!G179 -> 686913
A20: 12 | B20: 10.2.2 Pengiriman 1 set Panel dan Aksesoris RISHA T-36 | C20: set | D20: =AHS!G194 -> 1518000
A22: 13 | B22: 10.3 Pekerjaan Perakitan Panel RISHA
A23: 14 | B23: 10.3.1 Pekerjaan Perakitan Panel dan Alat Sambung Modul T36 RISHA | C23: unit | D23: =AHS!G224 -> 16766640
A24: 15 | B24: 10.3.2 Pekerjaan Perakitan Panel Modul T36 RISHA | C24: unit | D24: =AHS!G240 -> 112640

Sheet AHS
A1: 10 SISTEM STRUKTUR RISHA
A2: 10.1 Pekerjaan Produksi Panel RISHA
A3: 10.1.1 Pembuatan 1 buah Cetakan Panel P1 RISHA (Asumsi 400 kali pakai)
A4: No | B4: Uraian | C4: Kode | D4: Satuan | E4: Koefisien | F4: Harga Satuan (Rp.) | G4: Jumlah Harga (Rp.)
A5: A | B5: TENAGA KERJA
A6: 1 | B6: Pekerja | C6: L.01 | D6: OH | E6: 3,0959 | F6: =VLOOKUP(B6,'UPAH,BHN,ALAT'!$B$6:E239,4,FALSE) -> 10000 | G6: =E6*F6 -> 30959
A7: 2 | B7: Tukang Besi/Besi Beton | C7: L.02 | D7: OH | E7: 1,5479 | F7: =VLOOKUP(B7,'UPAH,BHN,ALAT'!$B$6:E240,4,FALSE) -> 10000 | G7: =E7*F7 -> 15479
A8: 3 | B8: Kepala Tukang | C8: L.03 | D8: OH | E8: 0,1548 | F8: =VLOOKUP(B8,'UPAH,BHN,ALAT'!$B$6:E241,4,FALSE) -> 10000 | G8: =E8*F8 -> 1548
A9: 4 | B9: Mandor | C9: L.04 | D9: OH | E9: 0,0516 | F9: =VLOOKUP(B9,'UPAH,BHN,ALAT'!$B$6:E242,4,FALSE) -> 10000 | G9: =E9*F9 -> 516
A10: Jumlah Harga Tenaga Kerja | G10: =SUM(G6:G9) -> 48502
A11: B | B11: BAHAN
A12: 1 | B12: Baja Profil | D12: kg | E12: 51,598 | F12: =VLOOKUP(B12,'UPAH,BHN,ALAT'!$B$6:E245,4,FALSE) -> 10000 | G12: =E12*F12 -> 515980
A13: 2 | B13: Kawat Las | D13: kg | E13: 0,053 | F13: =VLOOKUP(B13,'UPAH,BHN,ALAT'!$B$6:E246,4,FALSE) -> 10000 | G13: =E13*F13 -> 530
A14: Jumlah Harga Bahan | G14: =SUM(G11:G13) -> 516510
A15: C | B15: PERALATAN
A16: 1 | B16: Alat Las Listrik | D16: jam | E16: 0,0333 | F16: =VLOOKUP(B16,'UPAH,BHN,ALAT'!$B$6:E249,4,FALSE) -> 10000 | G16: =E16*F16 -> 333
A17: Jumlah Harga Alat | G17: =SUM(G16) -> 333
A18: D | B18: Jumlah Harga Tenaga Kerja, Bahan dan Peralatan (A+B+C) | G18: =SUM(G5:G17)/2 -> 565345
A19: E | B19: Biaya Umum dan Keuntungan (10% - 15%) x D | F19: 0.1 | G19: =G18*F19 -> 56534.5
A20: F | B20: Harga Satuan Pekerjaan (D+E) | G20: =ROUNDDOWN(G18+G19,0) -> 621879
A22: 10.1.2 Pembuatan 1 buah Cetakan Panel P2 RISHA (Asumsi 400 kali pakai)
A23: No | B23: Uraian | C23: Kode | D23: Satuan | E23: Koefisien | F23: Harga Satuan (Rp.) | G23: Jumlah Harga (Rp.)
A24: A | B24: TENAGA KERJA
A25: 1 | B25: Pekerja | C25: L.01 | D25: OH | E25: 2,7275 | F25: =VLOOKUP(B25,'UPAH,BHN,ALAT'!$B$6:E258,4,FALSE) -> 10000 | G25: =E25*F25 -> 27275
A26: 2 | B26: Tukang Besi/Besi Beton | C26: L.02 | D26: OH | E26: 1,3637 | F26: =VLOOKUP(B26,'UPAH,BHN,ALAT'!$B$6:E259,4,FALSE) -> 10000 | G26: =E26*F26 -> 13637
A27: 3 | B27: Kepala Tukang | C27: L.03 | D27: OH | E27: 0,1364 | F27: =VLOOKUP(B27,'UPAH,BHN,ALAT'!$B$6:E260,4,FALSE) -> 10000 | G27: =E27*F27 -> 1364
A28: 4 | B28: Mandor | C28: L.04 | D28: OH | E28: 0,0455 | F28: =VLOOKUP(B28,'UPAH,BHN,ALAT'!$B$6:E261,4,FALSE) -> 10000 | G28: =E28*F28 -> 455
A29: Jumlah Harga Tenaga Kerja | G29: =SUM(G25:G28) -> 42731
A30: B | B30: BAHAN
A31: 1 | B31: Baja Profil | D31: kg | E31: 45,458 | F31: =VLOOKUP(B31,'UPAH,BHN,ALAT'!$B$6:E264,4,FALSE) -> 10000 | G31: =E31*F31 -> 454580
A32: 2 | B32: Kawat Las | D32: kg | E32: 0,053 | F32: =VLOOKUP(B32,'UPAH,BHN,ALAT'!$B$6:E265,4,FALSE) -> 10000 | G32: =E32*F32 -> 530
A33: Jumlah Harga Bahan | G33: =SUM(G30:G32) -> 455110
A34: C | B34: PERALATAN
A35: 1 | B35: Alat Las Listrik | D35: jam | E35: 0,0333 | F35: =VLOOKUP(B35,'UPAH,BHN,ALAT'!$B$6:E268,4,FALSE) -> 10000 | G35: =E35*F35 -> 333
A36: Jumlah Harga Alat | G36: =SUM(G35) -> 333
A37: D | B37: Jumlah Harga Tenaga Kerja, Bahan dan Peralatan (A+B+C) | G37: =SUM(G25:G36)/2 -> 498174
A38: E | B38: Biaya Umum dan Keuntungan (10% - 15%) x D | F38: 0.1 | G38: =G37*F38 -> 49817.4
A39: F | B39: Harga Satuan Pekerjaan (D+E) | G39: =ROUNDDOWN(G37+G38,0) -> 547991
A41: 10.1.3 Pembuatan 1 buah Cetakan Panel P3 RISHA (Asumsi 400 kali pakai)
A42: No | B42: Uraian | C42: Kode | D42: Satuan | E42: Koefisien | F42: Harga Satuan (Rp.) | G42: Jumlah Harga (Rp.)
...

Sheet UPAH,BHN,ALAT
A1: HARGA SATUAN DASAR STRUKTUR RISHA
A2: UPAH TENAGA KERJA, BAHAN DAN PERALATAN
A4: NO. | B4: URAIAN | C4: KODE | D4: SATUAN | E4: HARGA | F4: KET.
A5: A. | B5: TENAGA KERJA
B6: Pekerja | D6: OH | E6: 10000
B7: Tukang Besi/Besi Beton | D7: OH | E7: 10000
B8: Pekerja | D8: OH | E8: 10000
B9: Mandor | D9: OH | E9: 10000
B10: Tukang Ereksi | D10: OH | E10: 10000
B11: Tukang batu/tembok | D11: OH | E11: 10000
B12: Kepala Tukang | D12: OH | E12: 10000
A14: B. | B14: BAHAN
A15: 1 | B15: Baja Profil | D15: kg | E15: 10000
A16: 2 | B16: Kawat Las | D16: kg | E16: 10000
A17: 3 | B17: Minyak Bekisting | D17: liter | E17: 10000
A18: 4 | B18: 1 kg Penulangan slab untuk BjTP diameter < 12 mm, cara Manual (untuk bangunan gedung) | D18: kg | E18: 10000
A19: 5 | B19: 1 kg Penulangan Wiremesh M6 untuk slab atau dinding atau Ferrocement secara manual (untuk bangunan gedung) | D19: m2 | E19: 10000
A20: 6 | B20: 1 m3 beton mutu sedang f'c 25 MPa, Slump (100 ± 25) mm, agregat maks 19 mm secara semi mekanis | D20: m3 | E20: 10000
A21: 7 | B21: Strapping Band lebar 15 mm | D21: m | E21: 10000
A22: 8 | B22: Palet Kayu Uk. 120 cm x 120 cm x 10 cm | D22: buah | E22: 10000
A23: 9 | B23: Kaso 5 x 7 Kayu Kelas 3 | D23: m3 | E23: 10000
A24: 10 | B24: Papan 2 /20 Kayu Kelas 3 | D24: m3 | E24: 10000
A25: 11 | B25: Paku 5 cm | D25: kg | E25: 10000
A26: 12 | B26: Panel P1 | D26: buah | E26: 10000
... A38: 24 | B38: Angkur Baja Full Drat ASTM 307 Ø 10 mm panjang 65 cm | D38: buah | E38: 10000
A39: B. | B39: BAHAN
B40: Alat Las Listrik | D40: jam | E40: 10000
